Workbook

Sheet Resumen
A1: WKH-2026 — Entrega N2: Gantt y presupuesto preliminar
A2: Plataforma de Reserva de Espacios de Trabajo WorkHub · Grupo 1 · Planificación integrada de plazos, costos y línea base.
A4: Resultados clave
A5: Inicio del proyecto | B5: =InicioProyecto -> 46296
A6: Fin del proyecto (plan) | B6: =Cronograma!H6 -> 46507
A7: Duración total (días hábiles) | B7: =NETWORKDAYS(InicioProyecto,Cronograma!H6,Feriados) -> 140
A8: Fin del trabajo previo al UAT (desarrollo, integraciones, piloto, capacitación) | B8: =MAX(Cronograma!H17,Cronograma!H19,Cronograma!H20,Cronograma!H25,Cronograma!H30,Cronograma!H32) -> 46405
A9: Inicio del UAT (5.3) | B9: =Cronograma!G33 -> 46462
A10: Colchón entre el fin del desarrollo y el UAT (días hábiles) | B10: =NETWORKDAYS(B8+1,B9-1,Feriados) -> 38
A11: Hitos del Acta cumplidos en el plan | B11: =COUNTIF(Cronograma!I39:I46,"OK")&" de "&ROWS(Cronograma!I39:I46) -> 8 de 8
A12: Costo base de actividades (USD) | B12: =Presupuesto!D50 -> 398000
A13: Línea base de costos (USD) | B13: =Presupuesto!D52 -> 420000
A14: Presupuesto del proyecto con reserva de gestión (USD) | B14: =Presupuesto!D54 -> 436800
A16: Qué contiene cada hoja
A17: Parámetros | B17: Fecha de inicio, ventana de balances, reservas, feriados y parámetros de solape de la cola.
A18: Cronograma | B18: Gantt calendarizado (31 filas), verificación de los hitos H-0 a H-7 del Acta y la ventana de balances.
A19: Presupuesto | B19: Costo por tarea y partidas no laborales, distribución mensual y conciliación con el Anexo A.
A20: Curva S | B20: Línea base de costos acumulada por mes, con sus dos gráficos.
A22: Decisiones y supuestos aplicados
A23: 1. Calendario lunes a viernes sin feriados nacionales. Los feriados 2026-2027 están cargados a mano en Parámetros y deben validarse.
A24: 2. La ventana de balances (01/01 al 15/03) se aplica solo al Gantt, no al diagrama de red (decisión del equipo): el UAT (5.3) no empieza antes del 16/03/2027 y el go-live (5.4) comienza el 31/03/2027 (H-6).
A25: 3. El camino crítico coloreado es el de la red lógica (AON). Las restricciones de calendario generan el colchón de la fila 10 entre el fin del desarrollo y el UAT; no es holgura de la red.
A26: 4. Cola con solapes (fast-tracking), tomando los rótulos del diagrama de red: 5.5 y 5.6 terminan 2 días hábiles después del fin de 5.4 (FF+2) y 1.6 termina junto con ellas (FF+0); además 3.5 empieza 10 días hábiles después del inicio de 2.6 (SS+10). Con la celda "Aplicar solapes" en 0 el cierre se corre más allá del 30/04/2027.
A27: 5. Predecesoras corregidas respecto de la lista anterior: 5.1 precede a 5.2 y 5.2 precede a 5.3.
A28: 6. Costos: las tareas valorizan solo mano de obra (lista de N2). La licencia WorkHub (USD 108.000) es una partida aparte, fechada a la firma. Los USD 28.000 que faltaban para llegar a USD 398.000 se asignan como tres partidas no laborales (13.000, 11.000 y 4.000), a documentar como supuesto S-10 en el Anexo E.
A29: 7. Conciliación con la inversión de N1 (sección 4.3, reproducida en el Anexo A): cierra en USD 398.000 de costo base y USD 420.000 de línea base (inversión total de N1, con la contingencia incluida). La N2 agrega, conforme al PMBOK 7, una reserva de gestión de USD 16.800 fuera de la línea base: presupuesto del proyecto USD 436.800. Quedan dos diferencias de USD 450 que se compensan entre Equipo Tandem + VCA e Integraciones.
A30: 8. Distribución de costos: lineal por día hábil entre el inicio y el fin de cada tarea. La contingencia se prorratea según el gasto mensual solo para dibujar la curva S.
A31: 9. Gestión del cambio: 4.1, 4.2, 4.4 y 4.5 se ejecutan en los meses 1 a 3 con la dedicación de 0,5 FTE de RR.HH. (R-6 de N1) y el apoyo del presupuesto de gestión del cambio. 4.3 (comunicación y campaña de lanzamiento) se programa no antes del 01/03/2027, con el referente de RR.HH. de jornada completa (meses 4 a 7, S-7); la comunicación no está restringida por R-3.
A32: Pendientes de decisión
A33: • Hitos con desvío entre el plan y el Acta (ver Cronograma, bloque de hitos): mover las fechas del Acta o comprimir tareas.
... A35: • Validar la lista de feriados contra el calendario oficial.

Sheet Parámetros
A1: Parámetros del modelo — WKH-2026
A2: Celdas en azul = entradas editables. Todo el modelo (Cronograma, Presupuesto, Curva S) se recalcula desde acá.
A3: Parámetro | B3: Valor | C3: Fuente / nota
A4: Inicio del proyecto (H-0, firma del Acta) | B4: 46296 | C4: Acta de constitución, hito H-0 (N1).
A5: Ventana de cierre de balances de VCA — desde | B5: 46388 | C5: Restricción 2.7 de N1: sin despliegue masivo ni capacitación.
A6: Ventana de cierre de balances de VCA — hasta | B6: 46461 | C6: Ídem. RI-5 reserva la ventana operativa desde el 16/03.
A7: Reserva para contingencias (USD) | B7: 22000 | C7: Sección 4.3 de N1, reproducida en el Anexo A (5,5 % del costo base de USD 398.000).
A8: Reserva de gestión (% sobre la línea base) | B8: 0.04 | C8: Agregada en N2 conforme al PMBOK 7 (la N1 no la definía). Queda fuera de la línea base; la libera el Comité mediante solicitud de cambio.
A9: Tolerancia de control (±) | B9: 0.1 | C9: Acta de constitución (N1), objetivo OP-1 y restricción R-1: banda de USD 378.000 a USD 462.000.
A10: Aplicar solapes en la cola del proyecto (1 = sí, 0 = no) | B10: 1 | C10: Fast-tracking de 5.5, 5.6 y 1.6 (ver Resumen). Con 0 todas las relaciones de la cola son Final-Inicio.
A11: Solape 3.5: inicio a N días hábiles del inicio de 2.6 (SS) | B11: 10 | C11: Rótulo "SS+10" del diagrama de red (2.6 → 3.5).
A12: Solape 5.5 y 5.6: fin N días hábiles después del fin de 5.4 (FF) | B12: 2 | C12: Rótulo "FF+2" del diagrama de red.
A13: Solape 1.6: fin N días hábiles después del fin de 5.5 y 5.6 (FF) | B13: 0 | C13: Supuesto nuevo: el cierre administrativo termina junto con 5.5 y 5.6.
A15: Feriados y días no laborables (excluidos del calendario)
A16: Fecha | B16: Descripción
A17: 46307 | B17: Día del Respeto a la Diversidad Cultural
A18: 46349 | B18: Día de la Soberanía Nacional (trasladado)
A19: 46363 | B19: Día no laborable con fines turísticos (puente)
A20: 46364 | B20: Inmaculada Concepción de María
A21: 46381 | B21: Navidad
A22: 46388 | B22: Año Nuevo
A23: 46426 | B23: Carnaval
A24: 46427 | B24: Carnaval
A25: 46470 | B25: Día de la Memoria
A26: 46471 | B26: Jueves Santo (no laborable)
A27: 46472 | B27: Viernes Santo
A28: 46479 | B28: Día del Veterano y de los Caídos en Malvinas
A30: Supuesto: los feriados y traslados 2026-2027 se cargaron de forma manual y deben validarse contra el calendario oficial (decretos de traslados y puentes). Para agregar uno, insertar una fila dentro del rango.

Sheet Cronograma
A1: WKH-2026 — Cronograma (diagrama de Gantt)
A2: Calendario lunes a viernes sin feriados (hoja Parámetros). Duraciones en días hábiles. Azul = entrada; negro = fórmula. | H2: Ventana de balances desde | J2: =BalIni -> 46388
H3: Ventana de balances hasta | J3: =BalFin -> 46461 | L3: Camino crítico (AON) | R3: Tarea con holgura | X3: Tarea resumen | AD3: Ventana de balances | AJ3: Restricción R-1 | AO3: ◆ plan ◇ Acta
K4: =K5 -> 46293 | L4: =IF(MONTH(L5)<>MONTH(K5),L5,"") -> 46300 | M4: =IF(MONTH(M5)<>MONTH(L5),M5,"") | N4: =IF(MONTH(N5)<>MONTH(M5),N5,"") | O4: =IF(MONTH(O5)<>MONTH(N5),O5,"") | P4: =IF(MONTH(P5)<>MONTH(O5),P5,"") -> 46328 | Q4: =IF(MONTH(Q5)<>MONTH(P5),Q5,"") | R4: =IF(MONTH(R5)<>MONTH(Q5),R5,"") | S4: =IF(MONTH(S5)<>MONTH(R5),S5,"") | ... AQ4: =IF(MONTH(AQ5)<>MONTH(AP5),AQ5,"")
A5: ID | B5: Tarea | C5: Responsable | D5: Dur. (d háb.) | E5: Predecesoras (lógica N2) | F5: Inicio no antes de | G5: Inicio | H5: Fin | I5: Crít. AON | J5: Chequeo ventana | K5: =InicioProyecto-WEEKDAY(InicioProyecto,2)+1 -> 46293 | L5: =K5+7 -> 46300 | M5: =L5+7 -> 46307 | N5: =M5+7 -> 46314 | O5: =N5+7 -> 46321 | P5: =O5+7 -> 46328 | Q5: =P5+7 -> 46335 | R5: =Q5+7 -> 46342 | S5: =R5+7 -> 46349 | ... AQ5: =AP5+7 -> 46517
A6: 1.5 | B6: Seguimiento, cambios e informes (tarea resumen) | C6: PM | D6: =NETWORKDAYS(G6,H6,Feriados) -> 133 | E6: 1.2, 1.3, 1.4 (hasta el cierre) | G6: =MAX(InicioProyecto,WORKDAY(MAX(H8,H9,H10),1,Feriados)) -> 46308 | H6: =MAX(H7:H36) -> 46507
A7: 1.1 | B7: Acta de constitución | C7: PM | D7: 2 | E7: — | G7: =MAX(InicioProyecto,N(F7)) -> 46296 | H7: =WORKDAY(G7,D7-1,Feriados) -> 46297 | I7: Sí
A8: 1.2 | B8: Declaración del alcance y EDT | C8: PM | D8: 5 | E8: 1.1 | G8: =MAX(InicioProyecto,N(F8),WORKDAY(MAX(H7),1,Feriados)) -> 46300 | H8: =WORKDAY(G8,D8-1,Feriados) -> 46304 | I8: Sí
A9: 1.3 | B9: Cronograma, presupuesto y línea base | C9: PM | D9: 5 | E9: 1.1 | G9: =MAX(InicioProyecto,N(F9),WORKDAY(MAX(H7),1,Feriados)) -> 46300 | H9: =WORKDAY(G9,D9-1,Feriados) -> 46304
A10: 1.4 | B10: Registro de riesgos e interesados | C10: PM | D10: 5 | E10: 1.1 | G10: =MAX(InicioProyecto,N(F10),WORKDAY(MAX(H7),1,Feriados)) -> 46300 | H10: =WORKDAY(G10,D10-1,Feriados) -> 46304
A11: 1.6 | B11: Cierre y lecciones aprendidas | C11: PM | D11: 5 | E11: 5.5, 5.6 (FF+0) | G11: =MAX(InicioProyecto,N(F11),IF(Solapes=1,MAX(WORKDAY(WORKDAY(H35,Parámetros!$B$13,Feriados),-(D11-1),Feriados),WORKDAY(WORKDAY(H36,Parámetros!$B$13,Feriados),-(D11-1),Feriados)),WORKDAY(MAX(H35,H36),1,Feriados))) -> 46503 | H11: =WORKDAY(G11,D11-1,Feriados) -> 46507 | I11: Sí
A12: 2.1 | B12: Relevamiento y reglas de negocio | C12: Product Owner | D12: 10 | E12: 1.2 | G12: =MAX(InicioProyecto,N(F12),WORKDAY(MAX(H8),1,Feriados)) -> 46308 | H12: =WORKDAY(G12,D12-1,Feriados) -> 46321 | I12: Sí
A13: 2.2 | B13: Planos e inventario de espacios | C13: Damián Sosa (SG, VCA) | D13: 15 | E13: 2.1 | G13: =MAX(InicioProyecto,N(F13),WORKDAY(MAX(H12),1,Feriados)) -> 46322 | H13: =WORKDAY(G13,D13-1,Feriados) -> 46342
A14: 2.3 | B14: Módulo de reserva de escritorios | C14: Equipo Frontend | D14: 16 | E14: 2.1 | G14: =MAX(InicioProyecto,N(F14),WORKDAY(MAX(H12),1,Feriados)) -> 46322 | H14: =WORKDAY(G14,D14-1,Feriados) -> 46343 | I14: Sí
A15: 2.4 | B15: Módulo de reserva de salas | C15: Equipo Frontend | D15: 15 | E15: 2.1 | G15: =MAX(InicioProyecto,N(F15),WORKDAY(MAX(H12),1,Feriados)) -> 46322 | H15: =WORKDAY(G15,D15-1,Feriados) -> 46342
A16: 2.5 | B16: Check-in, check-out y liberación | C16: Equipo Backend | D16: 12 | E16: 2.3 | G16: =MAX(InicioProyecto,N(F16),WORKDAY(MAX(H14),1,Feriados)) -> 46344 | H16: =WORKDAY(G16,D16-1,Feriados) -> 46360 | I16: Sí
A17: 2.6 | B17: Notificaciones y sugerencias | C17: Equipo Backend | D17: 15 | E17: 2.5, 3.2 | G17: =MAX(InicioProyecto,N(F17),WORKDAY(MAX(H16,H22),1,Feriados)) -> 46365 | H17: =WORKDAY(G17,D17-1,Feriados) -> 46386 | I17: Sí
A18: 2.7 | B18: Diseño UX | C18: Diseñador/a UX/UI | D18: 15 | E18: 2.1 | G18: =MAX(InicioProyecto,N(F18),WORKDAY(MAX(H12),1,Feriados)) -> 46322 | H18: =WORKDAY(G18,D18-1,Feriados) -> 46342
A19: 2.8 | B19: Implementación bot de Teams | C19: Equipo Backend | D19: 10 | E19: 2.7, 3.3 | G19: =MAX(InicioProyecto,N(F19),WORKDAY(MAX(H18,H23),1,Feriados)) -> 46343 | H19: =WORKDAY(G19,D19-1,Feriados) -> 46357
A20: 2.9 | B20: Configuración web | C20: Equipo Frontend | D20: 12 | E20: 2.5, 2.6, 2.7 | G20: =MAX(InicioProyecto,N(F20),WORKDAY(MAX(H16,H17,H18),1,Feriados)) -> 46387 | H20: =WORKDAY(G20,D20-1,Feriados) -> 46405 | I20: Sí
A21: 3.1 | B21: SSO y SCIM con Entra ID | C21: Equipo Backend y Tecnología VCA | D21: 12 | E21: 1.2 | G21: =MAX(InicioProyecto,N(F21),WORKDAY(MAX(H8),1,Feriados)) -> 46308 | H21: =WORKDAY(G21,D21-1,Feriados) -> 46323
A22: 3.2 | B22: Sincronización con HRIS | C22: Equipo Backend y Tecnología VCA | D22: 10 | E22: 3.1 | G22: =MAX(InicioProyecto,N(F22),WORKDAY(MAX(H21),1,Feriados)) -> 46324 | H22: =WORKDAY(G22,D22-1,Feriados) -> 46337
A23: 3.3 | B23: Exchange, Outlook y Teams | C23: Equipo Backend | D23: 10 | E23: 3.1 | G23: =MAX(InicioProyecto,N(F23),WORKDAY(MAX(H21),1,Feriados)) -> 46324 | H23: =WORKDAY(G23,D23-1,Feriados) -> 46337
A24: 3.4 | B24: Seguridad y endurecimiento | C24: Especialista QA | D24: 15 | E24: 3.2, 3.3 | G24: =MAX(InicioProyecto,N(F24),WORKDAY(MAX(H22,H23),1,Feriados)) -> 46338 | H24: =WORKDAY(G24,D24-1,Feriados) -> 46359
A25: 3.5 | B25: Pruebas de integración y carga | C25: Especialista QA | D25: 12 | E25: 3.4 (FS), 2.6 (SS+10) | G25: =MAX(InicioProyecto,N(F25),WORKDAY(MAX(H24),1,Feriados),WORKDAY(G17,Parámetros!$B$11,Feriados)) -> 46379 | H25: =WORKDAY(G25,D25-1,Feriados) -> 46398
A26: 4.1 | B26: Impacto e interesados con RR.HH. | C26: Soledad Ibarra (RR.HH., VCA) | D26: 10 | E26: 1.4 | G26: =MAX(InicioProyecto,N(F26),WORKDAY(MAX(H10),1,Feriados)) -> 46308 | H26: =WORKDAY(G26,D26-1,Feriados) -> 46321
A27: 4.2 | B27: Política de trabajo flexible | C27: Soledad Ibarra (RR.HH., VCA) | D27: 10 | E27: 4.1 | G27: =MAX(InicioProyecto,N(F27),WORKDAY(MAX(H26),1,Feriados)) -> 46322 | H27: =WORKDAY(G27,D27-1,Feriados) -> 46335
A28: 4.3 | B28: Comunicación y lanzamiento | C28: Soledad Ibarra (RR.HH., VCA) | D28: 15 | E28: 4.2 | F28: 46447 | G28: =MAX(InicioProyecto,N(F28),WORKDAY(MAX(H27),1,Feriados)) -> 46447 | H28: =WORKDAY(G28,D28-1,Feriados) -> 46465 | J28: OK (comunicación)
A29: 4.4 | B29: Referentes y capacitación | C29: Soledad Ibarra (RR.HH., VCA) | D29: 15 | E29: 4.2 | G29: =MAX(InicioProyecto,N(F29),WORKDAY(MAX(H27),1,Feriados)) -> 46336 | H29: =WORKDAY(G29,D29-1,Feriados) -> 46357 | J29: =IF(AND(G29<=BalFin,H29>=BalIni),"⚠ cae en ventana","OK") -> OK
A30: 4.5 | B30: Materiales y mesa de ayuda N1 | C30: Soledad Ibarra (RR.HH., VCA) | D30: 10 | E30: 4.4 | G30: =MAX(InicioProyecto,N(F30),WORKDAY(MAX(H29),1,Feriados)) -> 46358 | H30: =WORKDAY(G30,D30-1,Feriados) -> 46373
A31: 5.1 | B31: Ambientes, migración y despliegue | C31: Equipo Backend/Infra | D31: 12 | E31: 1.3 | G31: =MAX(InicioProyecto,N(F31),WORKDAY(MAX(H9),1,Feriados)) -> 46308 | H31: =WORKDAY(G31,D31-1,Feriados) -> 46323
A32: 5.2 | B32: Piloto y ajustes | C32: Carolina Méndez (PO) | D32: 20 | E32: 2.2, 2.3, 2.4, 2.7, 3.1, 4.2, 5.1 | G32: =MAX(InicioProyecto,N(F32),WORKDAY(MAX(H13,H14,H15,H18,H21,H27,H31),1,Feriados)) -> 46344 | H32: =WORKDAY(G32,D32-1,Feriados) -> 46374
A33: 5.3 | B33: UAT y acta de aceptación | C33: Especialista QA y Carolina Méndez (PO) | D33: 4 | E33: 2.6, 2.8, 2.9, 3.5, 4.5, 5.2 | F33: 46462 | G33: =MAX(InicioProyecto,N(F33),WORKDAY(MAX(H17,H19,H20,H25,H30,H32),1,Feriados)) -> 46462 | H33: =WORKDAY(G33,D33-1,Feriados) -> 46465 | I33: Sí | J33: =IF(AND(G33<=BalFin,H33>=BalIni),"⚠ cae en ventana","OK") -> OK
A34: 5.4 | B34: Go-live y estabilización (4 semanas) | C34: PM + equipo completo | D34: 20 | E34: 5.3, 4.3 | F34: 46477 | G34: =MAX(InicioProyecto,N(F34),WORKDAY(MAX(H33,H28),1,Feriados)) -> 46477 | H34: =WORKDAY(G34,D34-1,Feriados) -> 46505 | I34: Sí | J34: =IF(AND(G34<=BalFin,H34>=BalIni),"⚠ cae en ventana","OK") -> OK
A35: 5.5 | B35: Tablero y transferencia del seguimiento | C35: Carolina Méndez (PO) + VCA | D35: 10 | E35: 5.4 (FF+2) | G35: =MAX(InicioProyecto,N(F35),IF(Solapes=1,WORKDAY(WORKDAY(H34,Parámetros!$B$12,Feriados),-(D35-1),Feriados),WORKDAY(H34,1,Feriados))) -> 46496 | H35: =WORKDAY(G35,D35-1,Feriados) -> 46507 | I35: Sí
A36: 5.6 | B36: Informe de ocupación y recomendación | C36: Servicios Generales, VCA | D36: 10 | E36: 5.4 (FF+2) | G36: =MAX(InicioProyecto,N(F36),IF(Solapes=1,WORKDAY(WORKDAY(H34,Parámetros!$B$12,Feriados),-(D36-1),Feriados),WORKDAY(H34,1,Feriados))) -> 46496 | H36: =WORKDAY(G36,D36-1,Feriados) -> 46507 | I36: Sí
A38: ID | B38: Hitos del Acta (N1): fecha plan vs fecha del Acta | C38: Tarea que lo determina | E38: Criterio | F38: Fecha Acta | G38: Fecha plan | I38: Estado | J38: Δ días corridos
A39: H-0 | B39: Kick-off y firma del Acta | C39: 1.1 | E39: Inicio de 1.1 | F39: 46296 | G39: =G7 -> 46296 | I39: =IF(J39<=0,"OK","Desvío") -> OK | J39: =G39-F39 -> 0 | K39: =IF(AND($G39>=K$5,$G39<=K$5+6),"◆","")&IF(AND($F39>=K$5,$F39<=K$5+6),"◇","") -> ◆◇ | L39: =IF(AND($G39>=L$5,$G39<=L$5+6),"◆","")&IF(AND($F39>=L$5,$F39<=L$5+6),"◇","") | M39: =IF(AND($G39>=M$5,$G39<=M$5+6),"◆","")&IF(AND($F39>=M$5,$F39<=M$5+6),"◇","") | N39: =IF(AND($G39>=N$5,$G39<=N$5+6),"◆","")&IF(AND($F39>=N$5,$F39<=N$5+6),"◇","") | O39: =IF(AND($G39>=O$5,$G39<=O$5+6),"◆","")&IF(AND($F39>=O$5,$F39<=O$5+6),"◇","") | P39: =IF(AND($G39>=P$5,$G39<=P$5+6),"◆","")&IF(AND($F39>=P$5,$F39<=P$5+6),"◇","") | Q39: =IF(AND($G39>=Q$5,$G39<=Q$5+6),"◆","")&IF(AND($F39>=Q$5,$F39<=Q$5+6),"◇","") | R39: =IF(AND($G39>=R$5,$G39<=R$5+6),"◆","")&IF(AND($F39>=R$5,$F39<=R$5+6),"◇","") | ... AQ39: =IF(AND($G39>=AQ$5,$G39<=AQ$5+6),"◆","")&IF(AND($F39>=AQ$5,$F39<=AQ$5+6),"◇","")
A40: H-1 | B40: Alcance y EDT ratificados; línea base confirmada | C40: 1.2, 1.3 | E40: Fin de 1.2 y 1.3 | F40: 46312 | G40: =MAX(H8,H9) -> 46304 | I40: =IF(J40<=0,"OK","Desvío") -> OK | J40: =G40-F40 -> -8 | K40: =IF(AND($G40>=K$5,$G40<=K$5+6),"◆","")&IF(AND($F40>=K$5,$F40<=K$5+6),"◇","") | L40: =IF(AND($G40>=L$5,$G40<=L$5+6),"◆","")&IF(AND($F40>=L$5,$F40<=L$5+6),"◇","") -> ◆ | M40: =IF(AND($G40>=M$5,$G40<=M$5+6),"◆","")&IF(AND($F40>=M$5,$F40<=M$5+6),"◇","") -> ◇ | N40: =IF(AND($G40>=N$5,$G40<=N$5+6),"◆","")&IF(AND($F40>=N$5,$F40<=N$5+6),"◇","") | O40: =IF(AND($G40>=O$5,$G40<=O$5+6),"◆","")&IF(AND($F40>=O$5,$F40<=O$5+6),"◇","") | P40: =IF(AND($G40>=P$5,$G40<=P$5+6),"◆","")&IF(AND($F40>=P$5,$F40<=P$5+6),"◇","") | Q40: =IF(AND($G40>=Q$5,$G40<=Q$5+6),"◆","")&IF(AND($F40>=Q$5,$F40<=Q$5+6),"◇","") | R40: =IF(AND($G40>=R$5,$G40<=R$5+6),"◆","")&IF(AND($F40>=R$5,$F40<=R$5+6),"◇","") | ... AQ40: =IF(AND($G40>=AQ$5,$G40<=AQ$5+6),"◆","")&IF(AND($F40>=AQ$5,$F40<=AQ$5+6),"◇","")
A41: H-2 | B41: Diseño UX/UI y reglas validados; inventario cargado | C41: 2.1, 2.2, 2.7 | E41: Fin de 2.1, 2.2 y 2.7 | F41: 46347 | G41: =MAX(H12,H13,H18) -> 46342 | I41: =IF(J41<=0,"OK","Desvío") -> OK | J41: =G41-F41 -> -5 | K41: =IF(AND($G41>=K$5,$G41<=K$5+6),"◆","")&IF(AND($F41>=K$5,$F41<=K$5+6),"◇","") | L41: =IF(AND($G41>=L$5,$G41<=L$5+6),"◆","")&IF(AND($F41>=L$5,$F41<=L$5+6),"◇","") | M41: =IF(AND($G41>=M$5,$G41<=M$5+6),"◆","")&IF(AND($F41>=M$5,$F41<=M$5+6),"◇","") | N41: =IF(AND($G41>=N$5,$G41<=N$5+6),"◆","")&IF(AND($F41>=N$5,$F41<=N$5+6),"◇","") | O41: =IF(AND($G41>=O$5,$G41<=O$5+6),"◆","")&IF(AND($F41>=O$5,$F41<=O$5+6),"◇","") | P41: =IF(AND($G41>=P$5,$G41<=P$5+6),"◆","")&IF(AND($F41>=P$5,$F41<=P$5+6),"◇","") | Q41: =IF(AND($G41>=Q$5,$G41<=Q$5+6),"◆","")&IF(AND($F41>=Q$5,$F41<=Q$5+6),"◇","") | R41: =IF(AND($G41>=R$5,$G41<=R$5+6),"◆","")&IF(AND($F41>=R$5,$F41<=R$5+6),"◇","") -> ◆◇ | ... AQ41: =IF(AND($G41>=AQ$5,$G41<=AQ$5+6),"◆","")&IF(AND($F41>=AQ$5,$F41<=AQ$5+6),"◇","")
...

Sheet Presupuesto
A1: WKH-2026 — Presupuesto preliminar y línea base de costos
A2: Montos en USD. Mano de obra por tarea según la lista de tareas de N2; licencia y costos no laborales como partidas aparte. Azul = entrada; verde = vínculo a otra hoja; negro = fórmula.
A5: ID | B5: Concepto | C5: Tipo | D5: Categoría (Anexo A) | E5: Inicio | F5: Fin | G5: Costo (USD) | H5: =DATE(YEAR(InicioProyecto),MONTH(InicioProyecto),1) -> 46296 | I5: =EDATE(H5,1) -> 46327 | J5: =EDATE(I5,1) -> 46357 | K5: =EDATE(J5,1) -> 46388 | L5: =EDATE(K5,1) -> 46419 | M5: =EDATE(L5,1) -> 46447 | N5: =EDATE(M5,1) -> 46478 | O5: =EDATE(N5,1) -> 46508 | P5: Control
A6: =Cronograma!A6 -> 1.5 | B6: =Cronograma!B6 -> Seguimiento, cambios e informes (tarea resumen) | C6: Tarea | D6: Equipo Tandem + VCA | E6: =Cronograma!G6 -> 46308 | F6: =Cronograma!H6 -> 46507 | G6: 14000 | H6: =IF(NETWORKDAYS($E6,$F6,Feriados)<=0,0,$G6*MAX(0,NETWORKDAYS(MAX($E6,H$5),MIN($F6,EOMONTH(H$5,0)),Feriados))/NETWORKDAYS($E6,$F6,Feriados)) -> 1473.6842 | I6: =IF(NETWORKDAYS($E6,$F6,Feriados)<=0,0,$G6*MAX(0,NETWORKDAYS(MAX($E6,I$5),MIN($F6,EOMONTH(I$5,0)),Feriados))/NETWORKDAYS($E6,$F6,Feriados)) -> 2105.2632 | J6: =IF(NETWORKDAYS($E6,$F6,Feriados)<=0,0,$G6*MAX(0,NETWORKDAYS(MAX($E6,J$5),MIN($F6,EOMONTH(J$5,0)),Feriados))/NETWORKDAYS($E6,$F6,Feriados)) -> 2105.2632 | K6: =IF(NETWORKDAYS($E6,$F6,Feriados)<=0,0,$G6*MAX(0,NETWORKDAYS(MAX($E6,K$5),MIN($F6,EOMONTH(K$5,0)),Feriados))/NETWORKDAYS($E6,$F6,Feriados)) -> 2105.2632 | L6: =IF(NETWORKDAYS($E6,$F6,Feriados)<=0,0,$G6*MAX(0,NETWORKDAYS(MAX($E6,L$5),MIN($F6,EOMONTH(L$5,0)),Feriados))/NETWORKDAYS($E6,$F6,Feriados)) -> 1894.7368 | M6: =IF(NETWORKDAYS($E6,$F6,Feriados)<=0,0,$G6*MAX(0,NETWORKDAYS(MAX($E6,M$5),MIN($F6,EOMONTH(M$5,0)),Feriados))/NETWORKDAYS($E6,$F6,Feriados)) -> 2105.2632 | N6: =IF(NETWORKDAYS($E6,$F6,Feriados)<=0,0,$G6*MAX(0,NETWORKDAYS(MAX($E6,N$5),MIN($F6,EOMONTH(N$5,0)),Feriados))/NETWORKDAYS($E6,$F6,Feriados)) -> 2210.5263 | O6: =IF(NETWORKDAYS($E6,$F6,Feriados)<=0,0,$G6*MAX(0,NETWORKDAYS(MAX($E6,O$5),MIN($F6,EOMONTH(O$5,0)),Feriados))/NETWORKDAYS($E6,$F6,Feriados)) -> 0 | P6: =ROUND(SUM(H6:O6)-G6,2) -> 0
A7: =Cronograma!A7 -> 1.1 | B7: =Cronograma!B7 -> Acta de constitución | C7: Tarea | D7: Equipo Tandem + VCA | E7: =Cronograma!G7 -> 46296 | F7: =Cronograma!H7 -> 46297 | G7: 2700 | H7: =IF(NETWORKDAYS($E7,$F7,Feriados)<=0,0,$G7*MAX(0,NETWORKDAYS(MAX($E7,H$5),MIN($F7,EOMONTH(H$5,0)),Feriados))/NETWORKDAYS($E7,$F7,Feriados)) -> 2700 | I7: =IF(NETWORKDAYS($E7,$F7,Feriados)<=0,0,$G7*MAX(0,NETWORKDAYS(MAX($E7,I$5),MIN($F7,EOMONTH(I$5,0)),Feriados))/NETWORKDAYS($E7,$F7,Feriados)) -> 0 | J7: =IF(NETWORKDAYS($E7,$F7,Feriados)<=0,0,$G7*MAX(0,NETWORKDAYS(MAX($E7,J$5),MIN($F7,EOMONTH(J$5,0)),Feriados))/NETWORKDAYS($E7,$F7,Feriados)) -> 0 | K7: =IF(NETWORKDAYS($E7,$F7,Feriados)<=0,0,$G7*MAX(0,NETWORKDAYS(MAX($E7,K$5),MIN($F7,EOMONTH(K$5,0)),Feriados))/NETWORKDAYS($E7,$F7,Feriados)) -> 0 | L7: =IF(NETWORKDAYS($E7,$F7,Feriados)<=0,0,$G7*MAX(0,NETWORKDAYS(MAX($E7,L$5),MIN($F7,EOMONTH(L$5,0)),Feriados))/NETWORKDAYS($E7,$F7,Feriados)) -> 0 | M7: =IF(NETWORKDAYS($E7,$F7,Feriados)<=0,0,$G7*MAX(0,NETWORKDAYS(MAX($E7,M$5),MIN($F7,EOMONTH(M$5,0)),Feriados))/NETWORKDAYS($E7,$F7,Feriados)) -> 0 | N7: =IF(NETWORKDAYS($E7,$F7,Feriados)<=0,0,$G7*MAX(0,NETWORKDAYS(MAX($E7,N$5),MIN($F7,EOMONTH(N$5,0)),Feriados))/NETWORKDAYS($E7,$F7,Feriados)) -> 0 | O7: =IF(NETWORKDAYS($E7,$F7,Feriados)<=0,0,$G7*MAX(0,NETWORKDAYS(MAX($E7,O$5),MIN($F7,EOMONTH(O$5,0)),Feriados))/NETWORKDAYS($E7,$F7,Feriados)) -> 0 | P7: =ROUND(SUM(H7:O7)-G7,2) -> 0
A8: =Cronograma!A8 -> 1.2 | B8: =Cronograma!B8 -> Declaración del alcance y EDT | C8: Tarea | D8: Equipo Tandem + VCA | E8: =Cronograma!G8 -> 46300 | F8: =Cronograma!H8 -> 46304 | G8: 5400 | H8: =IF(NETWORKDAYS($E8,$F8,Feriados)<=0,0,$G8*MAX(0,NETWORKDAYS(MAX($E8,H$5),MIN($F8,EOMONTH(H$5,0)),Feriados))/NETWORKDAYS($E8,$F8,Feriados)) -> 5400 | I8: =IF(NETWORKDAYS($E8,$F8,Feriados)<=0,0,$G8*MAX(0,NETWORKDAYS(MAX($E8,I$5),MIN($F8,EOMONTH(I$5,0)),Feriados))/NETWORKDAYS($E8,$F8,Feriados)) -> 0 | J8: =IF(NETWORKDAYS($E8,$F8,Feriados)<=0,0,$G8*MAX(0,NETWORKDAYS(MAX($E8,J$5),MIN($F8,EOMONTH(J$5,0)),Feriados))/NETWORKDAYS($E8,$F8,Feriados)) -> 0 | K8: =IF(NETWORKDAYS($E8,$F8,Feriados)<=0,0,$G8*MAX(0,NETWORKDAYS(MAX($E8,K$5),MIN($F8,EOMONTH(K$5,0)),Feriados))/NETWORKDAYS($E8,$F8,Feriados)) -> 0 | L8: =IF(NETWORKDAYS($E8,$F8,Feriados)<=0,0,$G8*MAX(0,NETWORKDAYS(MAX($E8,L$5),MIN($F8,EOMONTH(L$5,0)),Feriados))/NETWORKDAYS($E8,$F8,Feriados)) -> 0 | M8: =IF(NETWORKDAYS($E8,$F8,Feriados)<=0,0,$G8*MAX(0,NETWORKDAYS(MAX($E8,M$5),MIN($F8,EOMONTH(M$5,0)),Feriados))/NETWORKDAYS($E8,$F8,Feriados)) -> 0 | N8: =IF(NETWORKDAYS($E8,$F8,Feriados)<=0,0,$G8*MAX(0,NETWORKDAYS(MAX($E8,N$5),MIN($F8,EOMONTH(N$5,0)),Feriados))/NETWORKDAYS($E8,$F8,Feriados)) -> 0 | O8: =IF(NETWORKDAYS($E8,$F8,Feriados)<=0,0,$G8*MAX(0,NETWORKDAYS(MAX($E8,O$5),MIN($F8,EOMONTH(O$5,0)),Feriados))/NETWORKDAYS($E8,$F8,Feriados)) -> 0 | P8: =ROUND(SUM(H8:O8)-G8,2) -> 0
A9: =Cronograma!A9 -> 1.3 | B9: =Cronograma!B9 -> Cronograma, presupuesto y línea base | C9: Tarea | D9: Equipo Tandem + VCA | E9: =Cronograma!G9 -> 46300 | F9: =Cronograma!H9 -> 46304 | G9: 5400 | H9: =IF(NETWORKDAYS($E9,$F9,Feriados)<=0,0,$G9*MAX(0,NETWORKDAYS(MAX($E9,H$5),MIN($F9,EOMONTH(H$5,0)),Feriados))/NETWORKDAYS($E9,$F9,Feriados)) -> 5400 | I9: =IF(NETWORKDAYS($E9,$F9,Feriados)<=0,0,$G9*MAX(0,NETWORKDAYS(MAX($E9,I$5),MIN($F9,EOMONTH(I$5,0)),Feriados))/NETWORKDAYS($E9,$F9,Feriados)) -> 0 | J9: =IF(NETWORKDAYS($E9,$F9,Feriados)<=0,0,$G9*MAX(0,NETWORKDAYS(MAX($E9,J$5),MIN($F9,EOMONTH(J$5,0)),Feriados))/NETWORKDAYS($E9,$F9,Feriados)) -> 0 | K9: =IF(NETWORKDAYS($E9,$F9,Feriados)<=0,0,$G9*MAX(0,NETWORKDAYS(MAX($E9,K$5),MIN($F9,EOMONTH(K$5,0)),Feriados))/NETWORKDAYS($E9,$F9,Feriados)) -> 0 | L9: =IF(NETWORKDAYS($E9,$F9,Feriados)<=0,0,$G9*MAX(0,NETWORKDAYS(MAX($E9,L$5),MIN($F9,EOMONTH(L$5,0)),Feriados))/NETWORKDAYS($E9,$F9,Feriados)) -> 0 | M9: =IF(NETWORKDAYS($E9,$F9,Feriados)<=0,0,$G9*MAX(0,NETWORKDAYS(MAX($E9,M$5),MIN($F9,EOMONTH(M$5,0)),Feriados))/NETWORKDAYS($E9,$F9,Feriados)) -> 0 | N9: =IF(NETWORKDAYS($E9,$F9,Feriados)<=0,0,$G9*MAX(0,NETWORKDAYS(MAX($E9,N$5),MIN($F9,EOMONTH(N$5,0)),Feriados))/NETWORKDAYS($E9,$F9,Feriados)) -> 0 | O9: =IF(NETWORKDAYS($E9,$F9,Feriados)<=0,0,$G9*MAX(0,NETWORKDAYS(MAX($E9,O$5),MIN($F9,EOMONTH(O$5,0)),Feriados))/NETWORKDAYS($E9,$F9,Feriados)) -> 0 | P9: =ROUND(SUM(H9:O9)-G9,2) -> 0
A10: =Cronograma!A10 -> 1.4 | B10: =Cronograma!B10 -> Registro de riesgos e interesados | C10: Tarea | D10: Equipo Tandem + VCA | E10: =Cronograma!G10 -> 46300 | F10: =Cronograma!H10 -> 46304 | G10: 4500 | H10: =IF(NETWORKDAYS($E10,$F10,Feriados)<=0,0,$G10*MAX(0,NETWORKDAYS(MAX($E10,H$5),MIN($F10,EOMONTH(H$5,0)),Feriados))/NETWORKDAYS($E10,$F10,Feriados)) -> 4500 | I10: =IF(NETWORKDAYS($E10,$F10,Feriados)<=0,0,$G10*MAX(0,NETWORKDAYS(MAX($E10,I$5),MIN($F10,EOMONTH(I$5,0)),Feriados))/NETWORKDAYS($E10,$F10,Feriados)) -> 0 | J10: =IF(NETWORKDAYS($E10,$F10,Feriados)<=0,0,$G10*MAX(0,NETWORKDAYS(MAX($E10,J$5),MIN($F10,EOMONTH(J$5,0)),Feriados))/NETWORKDAYS($E10,$F10,Feriados)) -> 0 | K10: =IF(NETWORKDAYS($E10,$F10,Feriados)<=0,0,$G10*MAX(0,NETWORKDAYS(MAX($E10,K$5),MIN($F10,EOMONTH(K$5,0)),Feriados))/NETWORKDAYS($E10,$F10,Feriados)) -> 0 | L10: =IF(NETWORKDAYS($E10,$F10,Feriados)<=0,0,$G10*MAX(0,NETWORKDAYS(MAX($E10,L$5),MIN($F10,EOMONTH(L$5,0)),Feriados))/NETWORKDAYS($E10,$F10,Feriados)) -> 0 | M10: =IF(NETWORKDAYS($E10,$F10,Feriados)<=0,0,$G10*MAX(0,NETWORKDAYS(MAX($E10,M$5),MIN($F10,EOMONTH(M$5,0)),Feriados))/NETWORKDAYS($E10,$F10,Feriados)) -> 0 | N10: =IF(NETWORKDAYS($E10,$F10,Feriados)<=0,0,$G10*MAX(0,NETWORKDAYS(MAX($E10,N$5),MIN($F10,EOMONTH(N$5,0)),Feriados))/NETWORKDAYS($E10,$F10,Feriados)) -> 0 | O10: =IF(NETWORKDAYS($E10,$F10,Feriados)<=0,0,$G10*MAX(0,NETWORKDAYS(MAX($E10,O$5),MIN($F10,EOMONTH(O$5,0)),Feriados))/NETWORKDAYS($E10,$F10,Feriados)) -> 0 | P10: =ROUND(SUM(H10:O10)-G10,2) -> 0
A11: =Cronograma!A11 -> 1.6 | B11: =Cronograma!B11 -> Cierre y lecciones aprendidas | C11: Tarea | D11: Equipo Tandem + VCA | E11: =Cronograma!G11 -> 46503 | F11: =Cronograma!H11 -> 46507 | G11: 4500 | H11: =IF(NETWORKDAYS($E11,$F11,Feriados)<=0,0,$G11*MAX(0,NETWORKDAYS(MAX($E11,H$5),MIN($F11,EOMONTH(H$5,0)),Feriados))/NETWORKDAYS($E11,$F11,Feriados)) -> 0 | I11: =IF(NETWORKDAYS($E11,$F11,Feriados)<=0,0,$G11*MAX(0,NETWORKDAYS(MAX($E11,I$5),MIN($F11,EOMONTH(I$5,0)),Feriados))/NETWORKDAYS($E11,$F11,Feriados)) -> 0 | J11: =IF(NETWORKDAYS($E11,$F11,Feriados)<=0,0,$G11*MAX(0,NETWORKDAYS(MAX($E11,J$5),MIN($F11,EOMONTH(J$5,0)),Feriados))/NETWORKDAYS($E11,$F11,Feriados)) -> 0 | K11: =IF(NETWORKDAYS($E11,$F11,Feriados)<=0,0,$G11*MAX(0,NETWORKDAYS(MAX($E11,K$5),MIN($F11,EOMONTH(K$5,0)),Feriados))/NETWORKDAYS($E11,$F11,Feriados)) -> 0 | L11: =IF(NETWORKDAYS($E11,$F11,Feriados)<=0,0,$G11*MAX(0,NETWORKDAYS(MAX($E11,L$5),MIN($F11,EOMONTH(L$5,0)),Feriados))/NETWORKDAYS($E11,$F11,Feriados)) -> 0 | M11: =IF(NETWORKDAYS($E11,$F11,Feriados)<=0,0,$G11*MAX(0,NETWORKDAYS(MAX($E11,M$5),MIN($F11,EOMONTH(M$5,0)),Feriados))/NETWORKDAYS($E11,$F11,Feriados)) -> 0 | N11: =IF(NETWORKDAYS($E11,$F11,Feriados)<=0,0,$G11*MAX(0,NETWORKDAYS(MAX($E11,N$5),MIN($F11,EOMONTH(N$5,0)),Feriados))/NETWORKDAYS($E11,$F11,Feriados)) -> 4500 | O11: =IF(NETWORKDAYS($E11,$F11,Feriados)<=0,0,$G11*MAX(0,NETWORKDAYS(MAX($E11,O$5),MIN($F11,EOMONTH(O$5,0)),Feriados))/NETWORKDAYS($E11,$F11,Feriados)) -> 0 | P11: =ROUND(SUM(H11:O11)-G11,2) -> 0
A12: =Cronograma!A12 -> 2.1 | B12: =Cronograma!B12 -> Relevamiento y reglas de negocio | C12: Tarea | D12: Equipo Tandem + VCA | E12: =Cronograma!G12 -> 46308 | F12: =Cronograma!H12 -> 46321 | G12: 7500 | H12: =IF(NETWORKDAYS($E12,$F12,Feriados)<=0,0,$G12*MAX(0,NETWORKDAYS(MAX($E12,H$5),MIN($F12,EOMONTH(H$5,0)),Feriados))/NETWORKDAYS($E12,$F12,Feriados)) -> 7500 | I12: =IF(NETWORKDAYS($E12,$F12,Feriados)<=0,0,$G12*MAX(0,NETWORKDAYS(MAX($E12,I$5),MIN($F12,EOMONTH(I$5,0)),Feriados))/NETWORKDAYS($E12,$F12,Feriados)) -> 0 | J12: =IF(NETWORKDAYS($E12,$F12,Feriados)<=0,0,$G12*MAX(0,NETWORKDAYS(MAX($E12,J$5),MIN($F12,EOMONTH(J$5,0)),Feriados))/NETWORKDAYS($E12,$F12,Feriados)) -> 0 | K12: =IF(NETWORKDAYS($E12,$F12,Feriados)<=0,0,$G12*MAX(0,NETWORKDAYS(MAX($E12,K$5),MIN($F12,EOMONTH(K$5,0)),Feriados))/NETWORKDAYS($E12,$F12,Feriados)) -> 0 | L12: =IF(NETWORKDAYS($E12,$F12,Feriados)<=0,0,$G12*MAX(0,NETWORKDAYS(MAX($E12,L$5),MIN($F12,EOMONTH(L$5,0)),Feriados))/NETWORKDAYS($E12,$F12,Feriados)) -> 0 | M12: =IF(NETWORKDAYS($E12,$F12,Feriados)<=0,0,$G12*MAX(0,NETWORKDAYS(MAX($E12,M$5),MIN($F12,EOMONTH(M$5,0)),Feriados))/NETWORKDAYS($E12,$F12,Feriados)) -> 0 | N12: =IF(NETWORKDAYS($E12,$F12,Feriados)<=0,0,$G12*MAX(0,NETWORKDAYS(MAX($E12,N$5),MIN($F12,EOMONTH(N$5,0)),Feriados))/NETWORKDAYS($E12,$F12,Feriados)) -> 0 | O12: =IF(NETWORKDAYS($E12,$F12,Feriados)<=0,0,$G12*MAX(0,NETWORKDAYS(MAX($E12,O$5),MIN($F12,EOMONTH(O$5,0)),Feriados))/NETWORKDAYS($E12,$F12,Feriados)) -> 0 | P12: =ROUND(SUM(H12:O12)-G12,2) -> 0
A13: =Cronograma!A13 -> 2.2 | B13: =Cronograma!B13 -> Planos e inventario de espacios | C13: Tarea | D13: Equipo Tandem + VCA | E13: =Cronograma!G13 -> 46322 | F13: =Cronograma!H13 -> 46342 | G13: 6750 | H13: =IF(NETWORKDAYS($E13,$F13,Feriados)<=0,0,$G13*MAX(0,NETWORKDAYS(MAX($E13,H$5),MIN($F13,EOMONTH(H$5,0)),Feriados))/NETWORKDAYS($E13,$F13,Feriados)) -> 1800 | I13: =IF(NETWORKDAYS($E13,$F13,Feriados)<=0,0,$G13*MAX(0,NETWORKDAYS(MAX($E13,I$5),MIN($F13,EOMONTH(I$5,0)),Feriados))/NETWORKDAYS($E13,$F13,Feriados)) -> 4950 | J13: =IF(NETWORKDAYS($E13,$F13,Feriados)<=0,0,$G13*MAX(0,NETWORKDAYS(MAX($E13,J$5),MIN($F13,EOMONTH(J$5,0)),Feriados))/NETWORKDAYS($E13,$F13,Feriados)) -> 0 | K13: =IF(NETWORKDAYS($E13,$F13,Feriados)<=0,0,$G13*MAX(0,NETWORKDAYS(MAX($E13,K$5),MIN($F13,EOMONTH(K$5,0)),Feriados))/NETWORKDAYS($E13,$F13,Feriados)) -> 0 | L13: =IF(NETWORKDAYS($E13,$F13,Feriados)<=0,0,$G13*MAX(0,NETWORKDAYS(MAX($E13,L$5),MIN($F13,EOMONTH(L$5,0)),Feriados))/NETWORKDAYS($E13,$F13,Feriados)) -> 0 | M13: =IF(NETWORKDAYS($E13,$F13,Feriados)<=0,0,$G13*MAX(0,NETWORKDAYS(MAX($E13,M$5),MIN($F13,EOMONTH(M$5,0)),Feriados))/NETWORKDAYS($E13,$F13,Feriados)) -> 0 | N13: =IF(NETWORKDAYS($E13,$F13,Feriados)<=0,0,$G13*MAX(0,NETWORKDAYS(MAX($E13,N$5),MIN($F13,EOMONTH(N$5,0)),Feriados))/NETWORKDAYS($E13,$F13,Feriados)) -> 0 | O13: =IF(NETWORKDAYS($E13,$F13,Feriados)<=0,0,$G13*MAX(0,NETWORKDAYS(MAX($E13,O$5),MIN($F13,EOMONTH(O$5,0)),Feriados))/NETWORKDAYS($E13,$F13,Feriados)) -> 0 | P13: =ROUND(SUM(H13:O13)-G13,2) -> 0
A14: =Cronograma!A14 -> 2.3 | B14: =Cronograma!B14 -> Módulo de reserva de escritorios | C14: Tarea | D14: Equipo Tandem + VCA | E14: =Cronograma!G14 -> 46322 | F14: =Cronograma!H14 -> 46343 | G14: 13500 | H14: =IF(NETWORKDAYS($E14,$F14,Feriados)<=0,0,$G14*MAX(0,NETWORKDAYS(MAX($E14,H$5),MIN($F14,EOMONTH(H$5,0)),Feriados))/NETWORKDAYS($E14,$F14,Feriados)) -> 3375 | I14: =IF(NETWORKDAYS($E14,$F14,Feriados)<=0,0,$G14*MAX(0,NETWORKDAYS(MAX($E14,I$5),MIN($F14,EOMONTH(I$5,0)),Feriados))/NETWORKDAYS($E14,$F14,Feriados)) -> 10125 | J14: =IF(NETWORKDAYS($E14,$F14,Feriados)<=0,0,$G14*MAX(0,NETWORKDAYS(MAX($E14,J$5),MIN($F14,EOMONTH(J$5,0)),Feriados))/NETWORKDAYS($E14,$F14,Feriados)) -> 0 | K14: =IF(NETWORKDAYS($E14,$F14,Feriados)<=0,0,$G14*MAX(0,NETWORKDAYS(MAX($E14,K$5),MIN($F14,EOMONTH(K$5,0)),Feriados))/NETWORKDAYS($E14,$F14,Feriados)) -> 0 | L14: =IF(NETWORKDAYS($E14,$F14,Feriados)<=0,0,$G14*MAX(0,NETWORKDAYS(MAX($E14,L$5),MIN($F14,EOMONTH(L$5,0)),Feriados))/NETWORKDAYS($E14,$F14,Feriados)) -> 0 | M14: =IF(NETWORKDAYS($E14,$F14,Feriados)<=0,0,$G14*MAX(0,NETWORKDAYS(MAX($E14,M$5),MIN($F14,EOMONTH(M$5,0)),Feriados))/NETWORKDAYS($E14,$F14,Feriados)) -> 0 | N14: =IF(NETWORKDAYS($E14,$F14,Feriados)<=0,0,$G14*MAX(0,NETWORKDAYS(MAX($E14,N$5),MIN($F14,EOMONTH(N$5,0)),Feriados))/NETWORKDAYS($E14,$F14,Feriados)) -> 0 | O14: =IF(NETWORKDAYS($E14,$F14,Feriados)<=0,0,$G14*MAX(0,NETWORKDAYS(MAX($E14,O$5),MIN($F14,EOMONTH(O$5,0)),Feriados))/NETWORKDAYS($E14,$F14,Feriados)) -> 0 | P14: =ROUND(SUM(H14:O14)-G14,2) -> 0
A15: =Cronograma!A15 -> 2.4 | B15: =Cronograma!B15 -> Módulo de reserva de salas | C15: Tarea | D15: Equipo Tandem + VCA | E15: =Cronograma!G15 -> 46322 | F15: =Cronograma!H15 -> 46342 | G15: 11250 | H15: =IF(NETWORKDAYS($E15,$F15,Feriados)<=0,0,$G15*MAX(0,NETWORKDAYS(MAX($E15,H$5),MIN($F15,EOMONTH(H$5,0)),Feriados))/NETWORKDAYS($E15,$F15,Feriados)) -> 3000 | I15: =IF(NETWORKDAYS($E15,$F15,Feriados)<=0,0,$G15*MAX(0,NETWORKDAYS(MAX($E15,I$5),MIN($F15,EOMONTH(I$5,0)),Feriados))/NETWORKDAYS($E15,$F15,Feriados)) -> 8250 | J15: =IF(NETWORKDAYS($E15,$F15,Feriados)<=0,0,$G15*MAX(0,NETWORKDAYS(MAX($E15,J$5),MIN($F15,EOMONTH(J$5,0)),Feriados))/NETWORKDAYS($E15,$F15,Feriados)) -> 0 | K15: =IF(NETWORKDAYS($E15,$F15,Feriados)<=0,0,$G15*MAX(0,NETWORKDAYS(MAX($E15,K$5),MIN($F15,EOMONTH(K$5,0)),Feriados))/NETWORKDAYS($E15,$F15,Feriados)) -> 0 | L15: =IF(NETWORKDAYS($E15,$F15,Feriados)<=0,0,$G15*MAX(0,NETWORKDAYS(MAX($E15,L$5),MIN($F15,EOMONTH(L$5,0)),Feriados))/NETWORKDAYS($E15,$F15,Feriados)) -> 0 | M15: =IF(NETWORKDAYS($E15,$F15,Feriados)<=0,0,$G15*MAX(0,NETWORKDAYS(MAX($E15,M$5),MIN($F15,EOMONTH(M$5,0)),Feriados))/NETWORKDAYS($E15,$F15,Feriados)) -> 0 | N15: =IF(NETWORKDAYS($E15,$F15,Feriados)<=0,0,$G15*MAX(0,NETWORKDAYS(MAX($E15,N$5),MIN($F15,EOMONTH(N$5,0)),Feriados))/NETWORKDAYS($E15,$F15,Feriados)) -> 0 | O15: =IF(NETWORKDAYS($E15,$F15,Feriados)<=0,0,$G15*MAX(0,NETWORKDAYS(MAX($E15,O$5),MIN($F15,EOMONTH(O$5,0)),Feriados))/NETWORKDAYS($E15,$F15,Feriados)) -> 0 | P15: =ROUND(SUM(H15:O15)-G15,2) -> 0
A16: =Cronograma!A16 -> 2.5 | B16: =Cronograma!B16 -> Check-in, check-out y liberación | C16: Tarea | D16: Equipo Tandem + VCA | E16: =Cronograma!G16 -> 46344 | F16: =Cronograma!H16 -> 46360 | G16: 9000 | H16: =IF(NETWORKDAYS($E16,$F16,Feriados)<=0,0,$G16*MAX(0,NETWORKDAYS(MAX($E16,H$5),MIN($F16,EOMONTH(H$5,0)),Feriados))/NETWORKDAYS($E16,$F16,Feriados)) -> 0 | I16: =IF(NETWORKDAYS($E16,$F16,Feriados)<=0,0,$G16*MAX(0,NETWORKDAYS(MAX($E16,I$5),MIN($F16,EOMONTH(I$5,0)),Feriados))/NETWORKDAYS($E16,$F16,Feriados)) -> 6000 | J16: =IF(NETWORKDAYS($E16,$F16,Feriados)<=0,0,$G16*MAX(0,NETWORKDAYS(MAX($E16,J$5),MIN($F16,EOMONTH(J$5,0)),Feriados))/NETWORKDAYS($E16,$F16,Feriados)) -> 3000 | K16: =IF(NETWORKDAYS($E16,$F16,Feriados)<=0,0,$G16*MAX(0,NETWORKDAYS(MAX($E16,K$5),MIN($F16,EOMONTH(K$5,0)),Feriados))/NETWORKDAYS($E16,$F16,Feriados)) -> 0 | L16: =IF(NETWORKDAYS($E16,$F16,Feriados)<=0,0,$G16*MAX(0,NETWORKDAYS(MAX($E16,L$5),MIN($F16,EOMONTH(L$5,0)),Feriados))/NETWORKDAYS($E16,$F16,Feriados)) -> 0 | M16: =IF(NETWORKDAYS($E16,$F16,Feriados)<=0,0,$G16*MAX(0,NETWORKDAYS(MAX($E16,M$5),MIN($F16,EOMONTH(M$5,0)),Feriados))/NETWORKDAYS($E16,$F16,Feriados)) -> 0 | N16: =IF(NETWORKDAYS($E16,$F16,Feriados)<=0,0,$G16*MAX(0,NETWORKDAYS(MAX($E16,N$5),MIN($F16,EOMONTH(N$5,0)),Feriados))/NETWORKDAYS($E16,$F16,Feriados)) -> 0 | O16: =IF(NETWORKDAYS($E16,$F16,Feriados)<=0,0,$G16*MAX(0,NETWORKDAYS(MAX($E16,O$5),MIN($F16,EOMONTH(O$5,0)),Feriados))/NETWORKDAYS($E16,$F16,Feriados)) -> 0 | P16: =ROUND(SUM(H16:O16)-G16,2) -> 0
A17: =Cronograma!A17 -> 2.6 | B17: =Cronograma!B17 -> Notificaciones y sugerencias | C17: Tarea | D17: Equipo Tandem + VCA | E17: =Cronograma!G17 -> 46365 | F17: =Cronograma!H17 -> 46386 | G17: 11250 | H17: =IF(NETWORKDAYS($E17,$F17,Feriados)<=0,0,$G17*MAX(0,NETWORKDAYS(MAX($E17,H$5),MIN($F17,EOMONTH(H$5,0)),Feriados))/NETWORKDAYS($E17,$F17,Feriados)) -> 0 | I17: =IF(NETWORKDAYS($E17,$F17,Feriados)<=0,0,$G17*MAX(0,NETWORKDAYS(MAX($E17,I$5),MIN($F17,EOMONTH(I$5,0)),Feriados))/NETWORKDAYS($E17,$F17,Feriados)) -> 0 | J17: =IF(NETWORKDAYS($E17,$F17,Feriados)<=0,0,$G17*MAX(0,NETWORKDAYS(MAX($E17,J$5),MIN($F17,EOMONTH(J$5,0)),Feriados))/NETWORKDAYS($E17,$F17,Feriados)) -> 11250 | K17: =IF(NETWORKDAYS($E17,$F17,Feriados)<=0,0,$G17*MAX(0,NETWORKDAYS(MAX($E17,K$5),MIN($F17,EOMONTH(K$5,0)),Feriados))/NETWORKDAYS($E17,$F17,Feriados)) -> 0 | L17: =IF(NETWORKDAYS($E17,$F17,Feriados)<=0,0,$G17*MAX(0,NETWORKDAYS(MAX($E17,L$5),MIN($F17,EOMONTH(L$5,0)),Feriados))/NETWORKDAYS($E17,$F17,Feriados)) -> 0 | M17: =IF(NETWORKDAYS($E17,$F17,Feriados)<=0,0,$G17*MAX(0,NETWORKDAYS(MAX($E17,M$5),MIN($F17,EOMONTH(M$5,0)),Feriados))/NETWORKDAYS($E17,$F17,Feriados)) -> 0 | N17: =IF(NETWORKDAYS($E17,$F17,Feriados)<=0,0,$G17*MAX(0,NETWORKDAYS(MAX($E17,N$5),MIN($F17,EOMONTH(N$5,0)),Feriados))/NETWORKDAYS($E17,$F17,Feriados)) -> 0 | O17: =IF(NETWORKDAYS($E17,$F17,Feriados)<=0,0,$G17*MAX(0,NETWORKDAYS(MAX($E17,O$5),MIN($F17,EOMONTH(O$5,0)),Feriados))/NETWORKDAYS($E17,$F17,Feriados)) -> 0 | P17: =ROUND(SUM(H17:O17)-G17,2) -> 0
... A36: =Cronograma!A36 -> 5.6 | B36: =Cronograma!B36 -> Informe de ocupación y recomendación | C36: Tarea | D36: Equipo Tandem + VCA | E36: =Cronograma!G36 -> 46496 | F36: =Cronograma!H36 -> 46507 | G36: 4500 | H36: =IF(NETWORKDAYS($E36,$F36,Feriados)<=0,0,$G36*MAX(0,NETWORKDAYS(MAX($E36,H$5),MIN($F36,EOMONTH(H$5,0)),Feriados))/NETWORKDAYS($E36,$F36,Feriados)) -> 0 | I36: =IF(NETWORKDAYS($E36,$F36,Feriados)<=0,0,$G36*MAX(0,NETWORKDAYS(MAX($E36,I$5),MIN($F36,EOMONTH(I$5,0)),Feriados))/NETWORKDAYS($E36,$F36,Feriados)) -> 0 | J36: =IF(NETWORKDAYS($E36,$F36,Feriados)<=0,0,$G36*MAX(0,NETWORKDAYS(MAX($E36,J$5),MIN($F36,EOMONTH(J$5,0)),Feriados))/NETWORKDAYS($E36,$F36,Feriados)) -> 0 | K36: =IF(NETWORKDAYS($E36,$F36,Feriados)<=0,0,$G36*MAX(0,NETWORKDAYS(MAX($E36,K$5),MIN($F36,EOMONTH(K$5,0)),Feriados))/NETWORKDAYS($E36,$F36,Feriados)) -> 0 | L36: =IF(NETWORKDAYS($E36,$F36,Feriados)<=0,0,$G36*MAX(0,NETWORKDAYS(MAX($E36,L$5),MIN($F36,EOMONTH(L$5,0)),Feriados))/NETWORKDAYS($E36,$F36,Feriados)) -> 0 | M36: =IF(NETWORKDAYS($E36,$F36,Feriados)<=0,0,$G36*MAX(0,NETWORKDAYS(MAX($E36,M$5),MIN($F36,EOMONTH(M$5,0)),Feriados))/NETWORKDAYS($E36,$F36,Feriados)) -> 0 | N36: =IF(NETWORKDAYS($E36,$F36,Feriados)<=0,0,$G36*MAX(0,NETWORKDAYS(MAX($E36,N$5),MIN($F36,EOMONTH(N$5,0)),Feriados))/NETWORKDAYS($E36,$F36,Feriados)) -> 4500 | O36: =IF(NETWORKDAYS($E36,$F36,Feriados)<=0,0,$G36*MAX(0,NETWORKDAYS(MAX($E36,O$5),MIN($F36,EOMONTH(O$5,0)),Feriados))/NETWORKDAYS($E36,$F36,Feriados)) -> 0 | P36: =ROUND(SUM(H36:O36)-G36,2) -> 0
A37: P-1 | B37: Licencia WorkHub: 1.200 usuarios con primer año de soporte | C37: Partida directa | D37: Licencia | E37: =InicioProyecto -> 46296 | F37: =InicioProyecto -> 46296 | G37: 108000 | H37: =IF(NETWORKDAYS($E37,$F37,Feriados)<=0,0,$G37*MAX(0,NETWORKDAYS(MAX($E37,H$5),MIN($F37,EOMONTH(H$5,0)),Feriados))/NETWORKDAYS($E37,$F37,Feriados)) -> 108000 | I37: =IF(NETWORKDAYS($E37,$F37,Feriados)<=0,0,$G37*MAX(0,NETWORKDAYS(MAX($E37,I$5),MIN($F37,EOMONTH(I$5,0)),Feriados))/NETWORKDAYS($E37,$F37,Feriados)) -> 0 | J37: =IF(NETWORKDAYS($E37,$F37,Feriados)<=0,0,$G37*MAX(0,NETWORKDAYS(MAX($E37,J$5),MIN($F37,EOMONTH(J$5,0)),Feriados))/NETWORKDAYS($E37,$F37,Feriados)) -> 0 | K37: =IF(NETWORKDAYS($E37,$F37,Feriados)<=0,0,$G37*MAX(0,NETWORKDAYS(MAX($E37,K$5),MIN($F37,EOMONTH(K$5,0)),Feriados))/NETWORKDAYS($E37,$F37,Feriados)) -> 0 | L37: =IF(NETWORKDAYS($E37,$F37,Feriados)<=0,0,$G37*MAX(0,NETWORKDAYS(MAX($E37,L$5),MIN($F37,EOMONTH(L$5,0)),Feriados))/NETWORKDAYS($E37,$F37,Feriados)) -> 0 | M37: =IF(NETWORKDAYS($E37,$F37,Feriados)<=0,0,$G37*MAX(0,NETWORKDAYS(MAX($E37,M$5),MIN($F37,EOMONTH(M$5,0)),Feriados))/NETWORKDAYS($E37,$F37,Feriados)) -> 0 | N37: =IF(NETWORKDAYS($E37,$F37,Feriados)<=0,0,$G37*MAX(0,NETWORKDAYS(MAX($E37,N$5),MIN($F37,EOMONTH(N$5,0)),Feriados))/NETWORKDAYS($E37,$F37,Feriados)) -> 0 | O37: =IF(NETWORKDAYS($E37,$F37,Feriados)<=0,0,$G37*MAX(0,NETWORKDAYS(MAX($E37,O$5),MIN($F37,EOMONTH(O$5,0)),Feriados))/NETWORKDAYS($E37,$F37,Feriados)) -> 0 | P37: =ROUND(SUM(H37:O37)-G37,2) -> 0
A38: P-2 | B38: Ambientes, observabilidad y licencias de soporte (parte no laboral) | C38: Partida no laboral | D38: Ambientes y observabilidad | E38: =Cronograma!G31 -> 46308 | F38: =Cronograma!H34 -> 46505 | G38: 13000 | H38: =IF(NETWORKDAYS($E38,$F38,Feriados)<=0,0,$G38*MAX(0,NETWORKDAYS(MAX($E38,H$5),MIN($F38,EOMONTH(H$5,0)),Feriados))/NETWORKDAYS($E38,$F38,Feriados)) -> 1389.313 | I38: =IF(NETWORKDAYS($E38,$F38,Feriados)<=0,0,$G38*MAX(0,NETWORKDAYS(MAX($E38,I$5),MIN($F38,EOMONTH(I$5,0)),Feriados))/NETWORKDAYS($E38,$F38,Feriados)) -> 1984.7328 | J38: =IF(NETWORKDAYS($E38,$F38,Feriados)<=0,0,$G38*MAX(0,NETWORKDAYS(MAX($E38,J$5),MIN($F38,EOMONTH(J$5,0)),Feriados))/NETWORKDAYS($E38,$F38,Feriados)) -> 1984.7328 | K38: =IF(NETWORKDAYS($E38,$F38,Feriados)<=0,0,$G38*MAX(0,NETWORKDAYS(MAX($E38,K$5),MIN($F38,EOMONTH(K$5,0)),Feriados))/NETWORKDAYS($E38,$F38,Feriados)) -> 1984.7328 | L38: =IF(NETWORKDAYS($E38,$F38,Feriados)<=0,0,$G38*MAX(0,NETWORKDAYS(MAX($E38,L$5),MIN($F38,EOMONTH(L$5,0)),Feriados))/NETWORKDAYS($E38,$F38,Feriados)) -> 1786.2595 | M38: =IF(NETWORKDAYS($E38,$F38,Feriados)<=0,0,$G38*MAX(0,NETWORKDAYS(MAX($E38,M$5),MIN($F38,EOMONTH(M$5,0)),Feriados))/NETWORKDAYS($E38,$F38,Feriados)) -> 1984.7328 | N38: =IF(NETWORKDAYS($E38,$F38,Feriados)<=0,0,$G38*MAX(0,NETWORKDAYS(MAX($E38,N$5),MIN($F38,EOMONTH(N$5,0)),Feriados))/NETWORKDAYS($E38,$F38,Feriados)) -> 1885.4962 | O38: =IF(NETWORKDAYS($E38,$F38,Feriados)<=0,0,$G38*MAX(0,NETWORKDAYS(MAX($E38,O$5),MIN($F38,EOMONTH(O$5,0)),Feriados))/NETWORKDAYS($E38,$F38,Feriados)) -> 0 | P38: =ROUND(SUM(H38:O38)-G38,2) -> 0
A39: P-3 | B39: Capacitación, comunicación y materiales (parte no laboral) | C39: Partida no laboral | D39: Gestión del cambio | E39: =MIN(Cronograma!G28,Cronograma!G29,Cronograma!G30) -> 46336 | F39: =MAX(Cronograma!H28,Cronograma!H29,Cronograma!H30) -> 46465 | G39: 11000 | H39: =IF(NETWORKDAYS($E39,$F39,Feriados)<=0,0,$G39*MAX(0,NETWORKDAYS(MAX($E39,H$5),MIN($F39,EOMONTH(H$5,0)),Feriados))/NETWORKDAYS($E39,$F39,Feriados)) -> 0 | I39: =IF(NETWORKDAYS($E39,$F39,Feriados)<=0,0,$G39*MAX(0,NETWORKDAYS(MAX($E39,I$5),MIN($F39,EOMONTH(I$5,0)),Feriados))/NETWORKDAYS($E39,$F39,Feriados)) -> 1770.1149 | J39: =IF(NETWORKDAYS($E39,$F39,Feriados)<=0,0,$G39*MAX(0,NETWORKDAYS(MAX($E39,J$5),MIN($F39,EOMONTH(J$5,0)),Feriados))/NETWORKDAYS($E39,$F39,Feriados)) -> 2528.7356 | K39: =IF(NETWORKDAYS($E39,$F39,Feriados)<=0,0,$G39*MAX(0,NETWORKDAYS(MAX($E39,K$5),MIN($F39,EOMONTH(K$5,0)),Feriados))/NETWORKDAYS($E39,$F39,Feriados)) -> 2528.7356 | L39: =IF(NETWORKDAYS($E39,$F39,Feriados)<=0,0,$G39*MAX(0,NETWORKDAYS(MAX($E39,L$5),MIN($F39,EOMONTH(L$5,0)),Feriados))/NETWORKDAYS($E39,$F39,Feriados)) -> 2275.8621 | M39: =IF(NETWORKDAYS($E39,$F39,Feriados)<=0,0,$G39*MAX(0,NETWORKDAYS(MAX($E39,M$5),MIN($F39,EOMONTH(M$5,0)),Feriados))/NETWORKDAYS($E39,$F39,Feriados)) -> 1896.5517 | N39: =IF(NETWORKDAYS($E39,$F39,Feriados)<=0,0,$G39*MAX(0,NETWORKDAYS(MAX($E39,N$5),MIN($F39,EOMONTH(N$5,0)),Feriados))/NETWORKDAYS($E39,$F39,Feriados)) -> 0 | O39: =IF(NETWORKDAYS($E39,$F39,Feriados)<=0,0,$G39*MAX(0,NETWORKDAYS(MAX($E39,O$5),MIN($F39,EOMONTH(O$5,0)),Feriados))/NETWORKDAYS($E39,$F39,Feriados)) -> 0 | P39: =ROUND(SUM(H39:O39)-G39,2) -> 0
A40: P-4 | B40: Licencias y soporte de proveedores de las integraciones (parte no laboral) | C40: Partida no laboral | D40: Integraciones | E40: =Cronograma!G21 -> 46308 | F40: =Cronograma!H25 -> 46398 | G40: 4000 | H40: =IF(NETWORKDAYS($E40,$F40,Feriados)<=0,0,$G40*MAX(0,NETWORKDAYS(MAX($E40,H$5),MIN($F40,EOMONTH(H$5,0)),Feriados))/NETWORKDAYS($E40,$F40,Feriados)) -> 933.33333 | I40: =IF(NETWORKDAYS($E40,$F40,Feriados)<=0,0,$G40*MAX(0,NETWORKDAYS(MAX($E40,I$5),MIN($F40,EOMONTH(I$5,0)),Feriados))/NETWORKDAYS($E40,$F40,Feriados)) -> 1333.3333 | J40: =IF(NETWORKDAYS($E40,$F40,Feriados)<=0,0,$G40*MAX(0,NETWORKDAYS(MAX($E40,J$5),MIN($F40,EOMONTH(J$5,0)),Feriados))/NETWORKDAYS($E40,$F40,Feriados)) -> 1333.3333 | K40: =IF(NETWORKDAYS($E40,$F40,Feriados)<=0,0,$G40*MAX(0,NETWORKDAYS(MAX($E40,K$5),MIN($F40,EOMONTH(K$5,0)),Feriados))/NETWORKDAYS($E40,$F40,Feriados)) -> 400 | L40: =IF(NETWORKDAYS($E40,$F40,Feriados)<=0,0,$G40*MAX(0,NETWORKDAYS(MAX($E40,L$5),MIN($F40,EOMONTH(L$5,0)),Feriados))/NETWORKDAYS($E40,$F40,Feriados)) -> 0 | M40: =IF(NETWORKDAYS($E40,$F40,Feriados)<=0,0,$G40*MAX(0,NETWORKDAYS(MAX($E40,M$5),MIN($F40,EOMONTH(M$5,0)),Feriados))/NETWORKDAYS($E40,$F40,Feriados)) -> 0 | N40: =IF(NETWORKDAYS($E40,$F40,Feriados)<=0,0,$G40*MAX(0,NETWORKDAYS(MAX($E40,N$5),MIN($F40,EOMONTH(N$5,0)),Feriados))/NETWORKDAYS($E40,$F40,Feriados)) -> 0 | O40: =IF(NETWORKDAYS($E40,$F40,Feriados)<=0,0,$G40*MAX(0,NETWORKDAYS(MAX($E40,O$5),MIN($F40,EOMONTH(O$5,0)),Feriados))/NETWORKDAYS($E40,$F40,Feriados)) -> 0 | P40: =ROUND(SUM(H40:O40)-G40,2) -> 0
B41: Costo base de actividades | G41: =SUM(G6:G40) -> 398000 | H41: =SUM(H6:H40) -> 175571.33 | I41: =SUM(I6:I40) -> 85768.444 | J41: =SUM(J6:J40) -> 43502.065 | K41: =SUM(K6:K40) -> 19168.732 | L41: =SUM(L6:L40) -> 5956.8585 | M41: =SUM(M6:M40) -> 20171.548 | N41: =SUM(N6:N40) -> 47861.022 | O41: =SUM(O6:O40) -> 0 | P41: =ROUND(SUM(P6:P40),2) -> 0
A43: Conciliación con la inversión de N1 (sección 4.3, reproducida en el Anexo A): top-down vs bottom-up
B44: Categoría | C44: N1 / Anexo A (USD) | D44: Bottom-up N2 (USD) | E44: Diferencia (USD) | F44: Observación
B45: Licencia | C45: 108000 | D45: =SUMIF($D$6:$D$40,$B45,$G$6:$G$40) -> 108000 | E45: =D45-C45 -> 0 | F45: Licencia WorkHub para 1.200 usuarios, con primer año de soporte.
B46: Equipo Tandem + VCA | C46: =168000+16000 -> 184000 | D46: =SUMIF($D$6:$D$40,$B46,$G$6:$G$40) -> 184450 | E46: =D46-C46 -> 450 | F46: Equipo de implementación de Tandem (168.000, 28 persona-mes) + horas del equipo interno de VCA (16.000). Tareas 1.x, 2.x y 5.2 a 5.6.
B47: Integraciones | C47: 46000 | D47: =SUMIF($D$6:$D$40,$B47,$G$6:$G$40) -> 45550 | E47: =D47-C47 -> -450 | F47: Desarrollo de integraciones corporativas. Tareas 3.x más la partida P-4.
B48: Ambientes y observabilidad | C48: 22000 | D48: =SUMIF($D$6:$D$40,$B48,$G$6:$G$40) -> 22000 | E48: =D48-C48 -> 0 | F48: Ambientes, migración, observabilidad y licencias de soporte del primer año. Tarea 5.1 más la partida P-2.
B49: Gestión del cambio | C49: 38000 | D49: =SUMIF($D$6:$D$40,$B49,$G$6:$G$40) -> 38000 | E49: =D49-C49 -> 0 | F49: Gestión del cambio, comunicación y capacitación. Tareas 4.x más la partida P-3.
B50: Costo base de actividades | C50: =SUM(C45:C49) -> 398000 | D50: =SUM(D45:D49) -> 398000 | E50: =D50-C50 -> 0 | F50: Debe coincidir con el costo total de la tabla de arriba (control en la fila siguiente).
B51: Reserva para contingencias | C51: =Parámetros!$B$7 -> 22000 | D51: =Parámetros!$B$7 -> 22000 | E51: =D51-C51 -> 0 | F51: Equivale a ~5,5 % del costo base. Responde a los riesgos con estrategia activa (apartado 1.10 de N1 y Anexo C).
B52: Línea base de costos | C52: =C50+C51 -> 420000 | D52: =D50+D51 -> 420000 | E52: =D52-C52 -> 0 | F52: Referencia de control: USD 420.000 ± 10 % (R-1 de N1). Coincide con la inversión total de N1.
B53: Reserva de gestión (fuera de la línea base) | C53: 0 | D53: =D52*Parámetros!$B$8 -> 16800 | E53: =D53-C53 -> 16800 | F53: Agregada en N2 conforme al PMBOK 7: 4 % de la línea base, para trabajo imprevisto dentro del alcance. La N1 no la definía.
B54: Presupuesto del proyecto (línea base + reserva de gestión) | C54: =C52+C53 -> 420000 | D54: =D52+D53 -> 436800 | E54: =D54-C54 -> 16800 | F54: La tolerancia de ± 10 % se mide sobre la línea base (USD 420.000), no sobre este total.
B56: Banda de tolerancia — límite inferior | D56: =D52*(1-Parámetros!$B$9) -> 378000
B57: Banda de tolerancia — límite superior | D57: =D52*(1+Parámetros!$B$9) -> 462000
B58: Control: distribución mensual = costo total | D58: =IF(AND(ABS(D50-G41)<0.5,ABS(P41)<0.5),"OK","REVISAR") -> OK
B59: Control: costo de actividades = inversión de N1 (USD 398.000) | D59: =IF(ABS(D50-C50)<0.5,"OK","REVISAR") -> OK
B61: Lectura de las diferencias: las dos diferencias de USD 450 se compensan entre sí (Equipo Tandem + VCA e Integraciones) y no alteran el total. Se dejan visibles en lugar de forzarlas.

Sheet Curva S
A1: WKH-2026 — Línea base de costos distribuida en el tiempo (curva S)
A2: USD. Distribución lineal por día hábil de cada tarea; licencia a la firma. La contingencia se prorratea según el gasto mensual (simplificación).
A4: Concepto | B4: =Presupuesto!H5 -> 46296 | C4: =Presupuesto!I5 -> 46327 | D4: =Presupuesto!J5 -> 46357 | E4: =Presupuesto!K5 -> 46388 | F4: =Presupuesto!L5 -> 46419 | G4: =Presupuesto!M5 -> 46447 | H4: =Presupuesto!N5 -> 46478 | I4: =Presupuesto!O5 -> 46508 | J4: Total
A5: Costo mensual de actividades | B5: =Presupuesto!H41 -> 175571.33 | C5: =Presupuesto!I41 -> 85768.444 | D5: =Presupuesto!J41 -> 43502.065 | E5: =Presupuesto!K41 -> 19168.732 | F5: =Presupuesto!L41 -> 5956.8585 | G5: =Presupuesto!M41 -> 20171.548 | H5: =Presupuesto!N41 -> 47861.022 | I5: =Presupuesto!O41 -> 0 | J5: =SUM(B5:I5) -> 398000
A6: Acumulado de actividades | B6: =B5 -> 175571.33 | C6: =B6+C5 -> 261339.77 | D6: =C6+D5 -> 304841.84 | E6: =D6+E5 -> 324010.57 | F6: =E6+F5 -> 329967.43 | G6: =F6+G5 -> 350138.98 | H6: =G6+H5 -> 398000 | I6: =H6+I5 -> 398000
A7: Contingencia prorrateada | B7: =IF($J$5=0,0,Parámetros!$B$7*B5/$J$5) -> 9704.9479 | C7: =IF($J$5=0,0,Parámetros!$B$7*C5/$J$5) -> 4740.9693 | D7: =IF($J$5=0,0,Parámetros!$B$7*D5/$J$5) -> 2404.6368 | E7: =IF($J$5=0,0,Parámetros!$B$7*E5/$J$5) -> 1059.5781 | F7: =IF($J$5=0,0,Parámetros!$B$7*F5/$J$5) -> 329.27358 | G7: =IF($J$5=0,0,Parámetros!$B$7*G5/$J$5) -> 1115.0102 | H7: =IF($J$5=0,0,Parámetros!$B$7*H5/$J$5) -> 2645.5842 | I7: =IF($J$5=0,0,Parámetros!$B$7*I5/$J$5) -> 0 | J7: =SUM(B7:I7) -> 22000
A8: Línea base mensual | B8: =B5+B7 -> 185276.28 | C8: =C5+C7 -> 90509.414 | D8: =D5+D7 -> 45906.702 | E8: =E5+E7 -> 20228.31 | F8: =F5+F7 -> 6286.132 | G8: =G5+G7 -> 21286.558 | H8: =H5+H7 -> 50506.607 | I8: =I5+I7 -> 0 | J8: =SUM(B8:I8) -> 420000
A9: Línea base acumulada | B9: =B8 -> 185276.28 | C9: =B9+C8 -> 275785.69 | D9: =C9+D8 -> 321692.39 | E9: =D9+E8 -> 341920.7 | F9: =E9+F8 -> 348206.84 | G9: =F9+G8 -> 369493.39 | H9: =G9+H8 -> 420000 | I9: =H9+I8 -> 420000
A10: Avance acumulado de la línea base (%) | B10: =IF($J$8=0,0,B9/$J$8) -> 0.441134 | C10: =IF($J$8=0,0,C9/$J$8) -> 0.6566326 | D10: =IF($J$8=0,0,D9/$J$8) -> 0.76593427 | E10: =IF($J$8=0,0,E9/$J$8) -> 0.81409691 | F10: =IF($J$8=0,0,F9/$J$8) -> 0.82906389 | G10: =IF($J$8=0,0,G9/$J$8) -> 0.87974617 | H10: =IF($J$8=0,0,H9/$J$8) -> 1 | I10: =IF($J$8=0,0,I9/$J$8) -> 1
