Workbook

Sheet Resumen
A1: WKH-2026 · Entrega N3 — Resumen y controles
A2: Grupo 1 · Docente: Mag. Ezequiel Pietracupa. Cada hoja tiene sus propias fórmulas de control; aquí se consolidan.
A4: Indicador | B4: Valor | C4: Hoja
A5: Componentes analizados (hacer o comprar) | B5: =COUNTA('Hacer o comprar'!A7:A17) -> 11 | C5: Hacer o comprar
A6: …de los cuales se compran | B6: =COUNTIF('Hacer o comprar'!P7:P17,"Comprar*") -> 7 | C6: Hacer o comprar
A7: …de los cuales se hacen | B7: =COUNTIF('Hacer o comprar'!P7:P17,"Hacer*") -> 4 | C7: Hacer o comprar
A8: Control hacer o comprar | B8: ='Hacer o comprar'!B19 -> OK: pesos 100 % y decisiones coherentes con el puntaje | C8: Hacer o comprar
A9: Contratos | B9: =COUNTA(Contratos!A5:A13) -> 9 | C9: Contratos
A10: Monto contratado (USD) | B10: =Contratos!F14 -> 353662 | C10: Contratos
A11: Control contratos = costo base N2 | B11: =Contratos!F17 -> OK: igual al costo base de la N2 | C11: Contratos
A12: Paquetes en la RACIS | B12: =COUNTA(RACIS!A6:A36) -> 31 | C12: RACIS
A13: Control RACIS | B13: =RACIS!C41 -> OK: 31 filas con un A y al menos un R | C13: RACIS
A14: Interesados registrados | B14: =COUNTA(Interesados!A5:A15) -> 11 | C14: Interesados
A15: Comunicaciones planificadas | B15: =COUNTA(Comunicaciones!A5:A21) -> 17 | C15: Comunicaciones
A16: Riesgos preliminares | B16: =COUNTA(Riesgos!A5:A21) -> 17 | C16: Riesgos
A17: …de prioridad alta | B17: =COUNTIF(Riesgos!H5:H21,"Alta") -> 5 | C17: Riesgos

Sheet Hacer o comprar
A1: Análisis de hacer o comprar — WKH-2026 · Entrega N3
A2: Puntajes de 1 a 5 (juicio de expertos del equipo, en azul: editables). Pesos editables en la fila 5; deben sumar 100 %. La decisión se recalcula; los requisitos excluyentes se anotan aparte.
A4: Criterio | C4: Costo | D4: Plazo y disponibilidad | E4: Capacidad y competencia interna | F4: Riesgo y calidad del resultado | G4: Control y restricciones | H4: Costo | I4: Plazo y disponibilidad | J4: Capacidad y competencia interna | K4: Riesgo y calidad del resultado | L4: Control y restricciones
A5: Pesos | B5: =SUM(C5:G5) -> 1 | C5: 0.3 | D5: 0.25 | E5: 0.2 | F5: 0.15 | G5: 0.1 | H5: =C5 -> 0.3 | I5: =D5 -> 0.25 | J5: =E5 -> 0.2 | K5: =F5 -> 0.15 | L5: =G5 -> 0.1
A6: ID | B6: Componente | C6: Hacer · Costo | D6: Hacer · Plazo y disponibilidad | E6: Hacer · Capacidad y competencia interna | F6: Hacer · Riesgo y calidad del resultado | G6: Hacer · Control y restricciones | H6: Comprar · Costo | I6: Comprar · Plazo y disponibilidad | J6: Comprar · Capacidad y competencia interna | K6: Comprar · Riesgo y calidad del resultado | L6: Comprar · Control y restricciones | M6: Puntaje hacer | N6: Puntaje comprar | O6: Decisión por puntaje | P6: Decisión adoptada | Q6: Opción hacer | R6: Opción comprar | S6: Fundamento / excluyente | T6: Partida N2
A7: C-1 | B7: Plataforma de reservas | C7: 1 | D7: 1 | E7: 2 | F7: 2 | G7: 5 | H7: 4 | I7: 5 | J7: 4 | K7: 4 | L7: 3 | M7: =SUMPRODUCT(C7:G7,$C$5:$G$5) -> 1.75 | N7: =SUMPRODUCT(H7:L7,$H$5:$L$5) -> 4.15 | O7: =IF(M7>N7,"Hacer","Comprar") -> Comprar | P7: Comprar | Q7: Desarrollo a medida (alternativa B de la N1: USD 610.000, 14 meses) | R7: Licencia WorkHub de Tandem (USD 108.000, perpetua) | S7: Ratifica la N1: el desarrollo propio excede plazo (R-2) e inversión. Se compra la licencia con primer año de soporte. | T7: P-1
A8: C-2 | B8: Implementación, configuración e integraciones | C8: 3 | D8: 1 | E8: 1 | F8: 2 | G8: 4 | H8: 3 | I8: 5 | J8: 5 | K8: 4 | L8: 3 | M8: =SUMPRODUCT(C8:G8,$C$5:$G$5) -> 2.05 | N8: =SUMPRODUCT(H8:L8,$H$5:$L$5) -> 4.05 | O8: =IF(M8>N8,"Hacer","Comprar") -> Comprar | P8: Comprar | Q8: Equipo interno de VCA | R8: Servicios de Tandem (licenciante e implementador) | S8: VCA solo puede asignar 0,5 FTE por área (R-6) y no tiene experiencia en WorkHub. Tandem aporta 10 perfiles. | T8: Mano de obra Tandem
A9: C-3 | B9: Infraestructura en la nube (ambientes de desarrollo, QA y producción) | C9: 4 | D9: 4 | E9: 4 | F9: 4 | G9: 5 | H9: 3 | I9: 5 | J9: 4 | K9: 3 | L9: 1 | M9: =SUMPRODUCT(C9:G9,$C$5:$G$5) -> 4.1 | N9: =SUMPRODUCT(H9:L9,$H$5:$L$5) -> 3.5 | O9: =IF(M9>N9,"Hacer","Comprar") -> Hacer | P9: Hacer | Q9: Aprovisionar en la suscripción Azure corporativa de VCA (Brasil Sur) | R9: Hosting gestionado por Tandem o un tercero | S9: R-5 exige la nube corporativa de VCA: el hosting de terceros no es admisible. Se consume bajo el contrato vigente de VCA. | T9: P-2a, P-2b, P-2c
A10: C-4 | B10: Observabilidad y herramientas del equipo (APM, CI/CD, backlog, bóveda de secretos) | C10: 3 | D10: 3 | E10: 3 | F10: 3 | G10: 4 | H10: 3 | I10: 5 | J10: 4 | K10: 4 | L10: 3 | M10: =SUMPRODUCT(C10:G10,$C$5:$G$5) -> 3.1 | N10: =SUMPRODUCT(H10:L10,$H$5:$L$5) -> 3.85 | O10: =IF(M10>N10,"Hacer","Comprar") -> Comprar | P10: Comprar | Q10: Instalar y operar herramientas de código abierto (≈ 8 días-persona de DevOps) | R10: Servicios gestionados por suscripción (USD 3.780 en 7 meses) | S10: Costo similar, pero la opción propia consume DevOps en el arranque (5.1) y suma operación. Las suscripciones quedan en el tenant de VCA. | T10: P-2d, P-2e
A11: C-5 | B11: Prueba de intrusión (RA-2) | C11: 4 | D11: 4 | E11: 2 | F11: 1 | G11: 4 | H11: 2 | I11: 4 | J11: 5 | K11: 5 | L11: 3 | M11: =SUMPRODUCT(C11:G11,$C$5:$G$5) -> 3.15 | N11: =SUMPRODUCT(H11:L11,$H$5:$L$5) -> 3.65 | O11: =IF(M11>N11,"Hacer","Comprar") -> Comprar | P11: Comprar | Q11: QA e Integraciones de Tandem (≈ 10 días-persona) | R11: Proveedor especializado e independiente (USD 7.500) | S11: Criterio excluyente: quien prueba no puede ser quien implementó (segregación de funciones). El equipo no tiene especialistas en pruebas ofensivas. | T11: P-4a
A12: C-6 | B12: Contenidos de adopción (piezas de campaña, videotutoriales y guías) | C12: 3 | D12: 2 | E12: 1 | F12: 3 | G12: 4 | H12: 3 | I12: 4 | J12: 5 | K12: 4 | L12: 3 | M12: =SUMPRODUCT(C12:G12,$C$5:$G$5) -> 2.45 | N12: =SUMPRODUCT(H12:L12,$H$5:$L$5) -> 3.8 | O12: =IF(M12>N12,"Hacer","Comprar") -> Comprar | P12: Comprar (mixto) | Q12: Producción con el equipo del proyecto | R12: Agencia de contenidos (USD 7.200) | S12: No hay diseño gráfico ni audiovisual en el equipo y el UX está en la plataforma. Guiones y mensajes los escriben Gestión del cambio y RR.HH.; la agencia produce. | T12: P-3a, P-3b
A13: C-7 | B13: Logística de capacitación (30 sesiones) | C13: 5 | D13: 4 | E13: 4 | F13: 4 | G13: 5 | H13: 2 | I13: 4 | J13: 4 | K13: 3 | L13: 2 | M13: =SUMPRODUCT(C13:G13,$C$5:$G$5) -> 4.4 | N13: =SUMPRODUCT(H13:L13,$H$5:$L$5) -> 3.05 | O13: =IF(M13>N13,"Hacer","Comprar") -> Hacer | P13: Hacer | Q13: Salas de Catalinas y referentes de VCA | R13: Capacitadora externa | S13: Las sesiones las dictan los referentes formados en 4.4 (efecto multiplicador). Solo se compran insumos menores. | T13: P-3c
A14: C-8 | B14: Encuestas de intención de uso y pulso | C14: 5 | D14: 4 | E14: 3 | F14: 2 | G14: 4 | H14: 4 | I14: 4 | J14: 4 | K14: 4 | L14: 3 | M14: =SUMPRODUCT(C14:G14,$C$5:$G$5) -> 3.8 | N14: =SUMPRODUCT(H14:L14,$H$5:$L$5) -> 3.9 | O14: =IF(M14>N14,"Hacer","Comprar") -> Comprar | P14: Comprar | Q14: Microsoft Forms (incluido en Microsoft 365) y análisis de RR.HH. | R14: Servicio de encuesta anónima (USD 900) | S14: Diferencia mínima (3,90 contra 3,80). Pesa el anonimato garantizado por un tercero frente a la resistencia (RI-3). Si Legal valida el anonimato con Forms, se hace y se liberan USD 900. | T14: P-3d
A15: C-9 | B15: Entornos sandbox de conectores (HRIS y Exchange) | C15: 4 | D15: 3 | E15: 3 | F15: 1 | G15: 3 | H15: 3 | I15: 4 | J15: 4 | K15: 5 | L15: 3 | M15: =SUMPRODUCT(C15:G15,$C$5:$G$5) -> 3 | N15: =SUMPRODUCT(H15:L15,$H$5:$L$5) -> 3.75 | O15: =IF(M15>N15,"Hacer","Comprar") -> Comprar | P15: Comprar | Q15: Simular los conectores con datos ficticios | R15: Entornos de prueba de los proveedores (USD 2.400) | S15: Simularlos no certifica la integración real (RA-3) y trasladaría los defectos a producción. | T15: P-4b
A16: C-10 | B16: Digitalización de planos e inventario de puestos | C16: 4 | D16: 4 | E16: 4 | F16: 4 | G16: 5 | H16: 2 | I16: 3 | J16: 4 | K16: 4 | L16: 3 | M16: =SUMPRODUCT(C16:G16,$C$5:$G$5) -> 4.1 | N16: =SUMPRODUCT(H16:L16,$H$5:$L$5) -> 3.05 | O16: =IF(M16>N16,"Hacer","Comprar") -> Hacer | P16: Hacer | Q16: Servicios Generales con los planos existentes y carga por DevOps | R16: Relevamiento y digitalización por un tercero | S16: Supuesto: Servicios Generales dispone de planos actualizados de las cuatro plantas. Si el relevamiento muestra que no, se compra el servicio por solicitud de cambio. | T16: Mano de obra (2.2)
A17: C-11 | B17: Mesa de ayuda de nivel 1 desde el go-live | C17: 5 | D17: 4 | E17: 4 | F17: 4 | G17: 5 | H17: 2 | I17: 4 | J17: 4 | K17: 3 | L17: 2 | M17: =SUMPRODUCT(C17:G17,$C$5:$G$5) -> 4.4 | N17: =SUMPRODUCT(H17:L17,$H$5:$L$5) -> 3.05 | O17: =IF(M17>N17,"Hacer","Comprar") -> Hacer | P17: Hacer | Q17: Mesa de ayuda corporativa de VCA con los materiales de 4.5 | R17: Tercerizar el nivel 1 en Tandem | S17: La mesa corporativa ya atiende a los 1.200 colaboradores. El nivel 2 lo cubre el contrato de mantenimiento (N1), fuera del proyecto. | T17: Mano de obra (4.5)
A19: Control | B19: =IF(AND(B5=1,SUMPRODUCT(--(LEFT(P7:P17,5)=LEFT(O7:O17,5)))=11),"OK: pesos 100 % y decisiones coherentes con el puntaje","REVISAR") -> OK: pesos 100 % y decisiones coherentes con el puntaje

Sheet Contratos
A1: Contratos, tipos y calendario de adjudicación
A2: Montos tomados del presupuesto de la N2 corregida (partidas y mano de obra de Tandem). El total más las horas de VCA debe dar el costo base de la N2.
A4: ID | B4: Objeto | C4: Proveedor | D4: Tipo de contrato | E4: Por qué ese tipo | F4: USD (N2) | G4: Pago | H4: Firma (S) | I4: Necesario desde | J4: Adjudicar / firmar | K4: Partidas N2 | L4: % del costo base
A5: K-1 | B5: Licencia WorkHub para 1.200 usuarios nominados | C5: Tandem Workplace Solutions S.R.L. | D5: Precio fijo cerrado (compraventa de licencia) | E5: Producto estándar con precio de lista: no hay incertidumbre de alcance. | F5: 108000 | G5: 100 % a la firma; primer año de soporte incluido | H5: Sponsor (VCA) y representante de Tandem | I5: 01/10/26 (H-0) | J5: Con la ratificación de H-1 (17/10/26) | K5: P-1 | L5: =F5/$F$16 -> 0.2897773
A6: K-2 | B6: Servicios de implementación (SOW-1) | C6: Tandem Workplace Solutions S.R.L. | D6: Precio fijo por entregables con pagos por hito; cambios por tiempo y materiales | E6: El alcance está cerrado en 31 paquetes con criterios de aceptación: el riesgo de costo queda en el proveedor. Los cambios aprobados se valorizan con el tarifario de la N2. | F6: 216888 | G6: Por hito aceptado (tabla de 1.3); el 20 % de H-7 se libera solo con el acta de cierre (RA-5) | H6: Sponsor (VCA) y representante de Tandem | I6: 01/10/26 (H-0) | J6: Con la ratificación de H-1 (17/10/26) | K6: Mano de obra Tandem | L6: =F6/$F$16 -> 0.58193721
A7: K-3 | B7: Ambientes en Azure y observabilidad (SOW-4) | C7: Microsoft, mediante el contrato corporativo vigente de VCA | D7: Precio unitario por consumo (ampliación del contrato existente) | E7: El consumo depende del uso real; VCA ya tiene el contrato y R-5 obliga a usarlo. | F7: 5494 | G7: Mensual, contra consumo | H7: Tecnología de VCA (dentro de su contrato) | I7: 14/10/26 (inicio de 5.1) | J7: Solicitud interna, 1–2 días hábiles | K7: P-2a a P-2d | L7: =F7/$F$16 -> 0.014741079
A8: K-4 | B8: Herramientas del equipo: CI/CD, backlog (Jira) y bóveda de secretos | C8: Proveedores SaaS, a nombre de VCA | D8: Precio unitario (suscripción mensual por usuario) | E8: Servicio estándar, cancelable al cierre; la propiedad del código y del backlog queda en VCA. | F8: 1680 | G8: Mensual | H8: PM | I8: 14/10/26 (inicio de 5.1) | J8: Compra directa | K8: P-2e | L8: =F8/$F$16 -> 0.0045076469
A9: K-5 | B9: Prueba de intrusión externa (SOW-2) | C9: A seleccionar entre tres oferentes independientes de Tandem | D9: Precio fijo cerrado | E9: Alcance acotado y verificable (objetivos, metodología, re-test): el oferente puede cotizar con certeza. | F9: 7500 | G9: 100 % contra informe final y re-test aceptados | H9: Sponsor (VCA) | I9: 13/11/26 (inicio de 3.4) | J9: 06/11/26 | K9: P-4a | L9: =F9/$F$16 -> 0.020123424
A10: K-6 | B10: Contenidos de adopción (SOW-3) | C10: Agencia de contenidos a seleccionar (tres cotizaciones) | D10: Precio unitario por pieza (orden de compra abierta) | E10: Cantidades conocidas y precio por pieza; permite ajustar piezas sin renegociar. | F10: 7200 | G10: Por pieza aceptada por RR.HH. | H10: Sponsor (VCA) | I10: 10/11/26 (inicio de 4.4); piezas de campaña al 01/03/27 | J10: 30/10/26 (orden 1) y 12/02/27 (orden 2) | K10: P-3a, P-3b | L10: =F10/$F$16 -> 0.019318487
A11: K-7 | B11: Entornos sandbox de HRIS y Exchange | C11: Proveedor del HRIS y Microsoft (tenant de pruebas) | D11: Precio fijo por entorno | E11: Servicio estándar de los fabricantes, sin variación de alcance. | F11: 2400 | G11: A la habilitación | H11: PM (proveedor único) | I11: 30/10/26 (inicio de 3.2 y 3.3) | J11: 23/10/26 | K11: P-4b | L11: =F11/$F$16 -> 0.0064394956
A12: K-8 | B12: Encuesta anónima de intención de uso y pulso | C12: Proveedor de encuestas a seleccionar | D12: Precio fijo cerrado | E12: Servicio acotado; garantiza el anonimato de las respuestas. | F12: 900 | G12: Contra informe de resultados | H12: PM | I12: 13/10/26 (4.1, en curso) | J12: Compra directa | K12: P-3d | L12: =F12/$F$16 -> 0.0024148108
A13: K-9 | B13: Insumos de capacitación para 30 sesiones | C13: Proveedores habituales de VCA | D13: Orden de compra (precio unitario) | E13: Compra menor recurrente. | F13: 3600 | G13: Contra entrega | H13: Sponsor (orden de compra de RR.HH.) | I13: 10/11/26 (inicio de 4.4) | J13: 03/11/26 (tres cotizaciones) | K13: P-3c | L13: =F13/$F$16 -> 0.0096592434
A14: Total | F14: =SUM(F5:F13) -> 353662
A15: Horas de VCA (N2) | F15: 19038
A16: Costo base N2 | F16: =F14+F15 -> 372700
A17: Control | F17: =IF(F16=372700,"OK: igual al costo base de la N2","REVISAR") -> OK: igual al costo base de la N2
A19: Pagos por hito del contrato K-2 (servicios de implementación)
A20: Hito | B20: Fecha plan | C20: Entregable que habilita el pago | D20: % | E20: USD
A21: H-2 | B21: 17/11/26 | C21: Diseño UX/UI y reglas validados; inventario cargado | D21: 0.15 | E21: =D21*$F$6 -> 32533.2
A22: H-3 | B22: 18/12/26 | C22: Piloto de la planta 3 completado | D22: 0.2 | E22: =D22*$F$6 -> 43377.6
A23: H-4 | B23: 07/01/27 | C23: Notificaciones completas; seguridad, integración y carga superadas | D23: 0.2 | E23: =D23*$F$6 -> 43377.6
A24: H-5 | B24: 19/03/27 | C24: UAT aceptada (acta firmada) | D24: 0.15 | E24: =D24*$F$6 -> 32533.2
A25: H-6 | B25: 31/03/27 | C25: Puesta en producción en las cuatro plantas | D25: 0.1 | E25: =D25*$F$6 -> 21688.8
A26: H-7 | B26: 30/04/27 | C26: Cierre, estabilización, tablero e informe aceptados (pago final, actúa como retención) | D26: 0.2 | E26: =D26*$F$6 -> 43377.6
C27: Total | D27: =SUM(D21:D26) -> 1 | E27: =SUM(E21:E26) -> 216888
C28: Control | D28: =IF(D27=1,"OK","REVISAR") -> OK
A30: Reglas de compra (del plan; a validar con la política de compras de VCA)
A31: Monto | B31: Procedimiento | C31: Aprueba
A32: Hasta USD 2.500 | B32: Compra directa con una cotización | C32: PM
A33: USD 2.500 a USD 10.000 | B33: Tres cotizaciones comparables y matriz de evaluación | C33: Sponsor
A34: Más de USD 10.000 o contrato principal | B34: Contrato con SOW y revisión legal y de seguridad | C34: Sponsor (el Comité ya lo aprobó en el caso de negocio)
A35: Ampliación de un contrato vigente de VCA | B35: Según el contrato original | C35: Área titular del contrato
A37: Matriz de evaluación de ofertas (K-5, K-6 y K-9): puntaje de 1 a 5 por oferente
A38: Criterio | B38: Peso | C38: Oferente 1 | D38: Oferente 2 | E38: Oferente 3
A39: Experiencia y certificaciones del equipo | B39: 0.3
A40: Metodología y alcance propuesto | B40: 0.25
A41: Precio | B41: 0.3
A42: Plazo y disponibilidad en la ventana | B42: 0.15
A43: Puntaje ponderado | B43: =SUM(B39:B42) -> 1 | C43: =IF(COUNT(C39:C42)=0,"",SUMPRODUCT(C39:C42,$B$39:$B$42)) | D43: =IF(COUNT(D39:D42)=0,"",SUMPRODUCT(D39:D42,$B$39:$B$42)) | E43: =IF(COUNT(E39:E42)=0,"",SUMPRODUCT(E39:E42,$B$39:$B$42))

Sheet SOW
A1: Enunciados del trabajo (SOW)
A2: Un bloque por componente a contratar.
A4: SOW-1 · Servicios de implementación de WorkHub (contrato K-2)
A5: Objeto | B5: Configuración, integración, pruebas, despliegue y estabilización de WorkHub en la sede Catalinas, con gestión del cambio, según la EDT de 31 paquetes (N1) y el plan de la N2.
A6: Alcance | B6: Paquetes 1.1–1.6, 2.1–2.9, 3.1–3.5, 4.1–4.5 y 5.1–5.6 en la parte que ejecuta Tandem. Excluye las tareas de VCA (planos, política, mesa de ayuda) y las exclusiones E-1 a E-13 de la N1.
A7: Equipo mínimo | B7: PM, PO, UX/UI, 2 desarrolladores full-stack, QA, 2 ingenieros de integraciones, DevOps y consultor/a de gestión del cambio. El reemplazo de una persona clave requiere aviso de 10 días hábiles y un perfil equivalente aprobado por VCA.
A8: Entregables y aceptación | B8: Los cinco macro-entregables con los criterios de aceptación por entregable de la N1 (2.4). Cada hito de pago exige acta firmada por quien figura con S en la RACIS.
A9: Plazo y lugar | B9: 01/10/2026 – 30/04/2027; trabajo híbrido entre las oficinas de Tandem y Catalinas, presencial en piloto, UAT y go-live.
A10: Precio y pago | B10: Precio fijo de USD 216.888 (estimación de la N2 a negociar), pagado por hitos; el último pago (20 %) se libera con el acta de cierre. Cambios aprobados por el Comité: tiempo y materiales con el tarifario de la N2, financiados con la reserva de gestión.
A11: Propiedad y datos | B11: Configuración, scripts, documentación y backlog son de VCA y quedan en su tenant. Confidencialidad y tratamiento de datos según la Ley 25.326 y la política de VCA (R-4).
A13: SOW-2 · Prueba de intrusión externa (contrato K-5)
A14: Objeto | B14: Prueba de intrusión de caja gris sobre la instancia de WorkHub de VCA: aplicación web, bot de Teams, APIs e inicio de sesión único.
A15: Metodología | B15: OWASP Web Security Testing Guide y OWASP Top 10; severidad de hallazgos con CVSS v3.1. Pruebas en el ambiente de QA/staging, nunca en producción.
A16: Entregables | B16: Plan de pruebas aprobado; informe ejecutivo y técnico con evidencia y recomendaciones; re-test de los hallazgos críticos y altos.
A17: Plazo | B17: Del 13/11 al 04/12/2026 (dentro de 3.4): 8 días hábiles de pruebas, informe al 26/11 y re-test antes del 04/12.
A18: Requisitos del proveedor | B18: Sin vínculo societario ni comercial con Tandem; equipo con certificación en pruebas ofensivas (OSCP o equivalente); acuerdo de confidencialidad y de tratamiento de datos.
A19: Aceptación | B19: Seguridad de la Información de VCA firma el informe final: cero hallazgos críticos o altos abiertos (RA-2).
A20: Precio y pago | B20: Precio fijo de USD 7.500; 100 % contra informe final y re-test aceptados.
A22: SOW-3 · Contenidos de adopción (contrato K-6)
A23: Objeto | B23: Producción de 8 materiales de capacitación (videotutoriales de hasta 3 minutos con guía PDF) y 12 piezas de la campaña de lanzamiento.
A24: Insumos de VCA y Tandem | B24: Guiones y mensajes de Gestión del cambio y RR.HH.; capturas del ambiente de QA con datos ficticios; manual de marca de VCA.
A25: Requisitos | B25: Subtítulos en todos los videos; formatos para correo, Teams, intranet y pantallas de la sede; sin datos personales reales; dos rondas de revisión por pieza.
A26: Plazo | B26: Orden 1 (materiales): del 10/11 al 17/12/2026, para 4.4 y 4.5. Orden 2 (campaña): entrega al 26/02/2027 para 4.3, que empieza el 01/03.
A27: Aceptación y pago | B27: RR.HH. de VCA acepta cada pieza; pago por pieza aceptada (USD 450 por material, USD 300 por pieza de campaña).
A29: SOW-4 · Ambientes en Azure y observabilidad (contrato K-3)
A30: Objeto | B30: Ambientes de desarrollo y QA/staging desde el 14/10/2026, producción desde la preproducción de marzo, y monitoreo de aplicación y registros.
A31: Requisitos | B31: Región Brasil Sur, dentro de la suscripción corporativa de VCA (R-5); acceso por roles con cuentas de Entra ID; copias de seguridad diarias; separación de datos de prueba y de producción.
A32: Responsables | B32: Tecnología de VCA aprueba y paga el consumo; DevOps de Tandem aprovisiona y opera dentro de los permisos asignados.
A33: Aceptación | B33: Tecnología de VCA verifica cada ambiente antes de su uso; el de producción, antes del go-live del 31/03/2027.
A34: Precio | B34: Consumo estimado de USD 5.494 en el proyecto (N2); desde el mes 13, hosting de USD 5.060 anuales del caso de negocio.

Sheet RACIS
A1: Matriz RACIS — 31 paquetes de la EDT
A2: R ejecuta · A rinde cuentas (uno por fila) · C consultado · I informado · S firma. Varias letras se separan con coma. Las columnas de control validan las reglas de la cátedra.
A4: Paquete | B4: Nombre | C4: Sponsor | D4: Project Manager | E4: Product Owner | F4: UX/UI | G4: Desarrollo full-stack (2) | H4: QA | I4: Integraciones (2) | J4: DevOps | K4: Gestión del cambio | L4: Tecnología VCA | M4: Servicios Generales VCA | N4: RR.HH. VCA | O4: Seguridad de la Información VCA | P4: Proveedor de pruebas de intrusión | Q4: Agencia de contenidos | R4: Cantidad de A | S4: Cantidad de R | T4: Control de fila
B5: Persona u organización | C5: Mariana Ferreyra, CFO de VCA | D5: Julián Ferrari, Tandem | E5: Carolina Méndez, Tandem | F5: Tandem | G5: Tandem | H5: Tandem | I5: Tandem | J5: Tandem | K5: Tandem | L5: Pablo Guzmán | M5: Damián Sosa | N5: Soledad Ibarra | O5: VCA | P5: externo (K-5) | Q5: externo (K-6)
A6: 1.1 | B6: Acta de constitución | C6: A, S | D6: R, S | R6: =COUNTIF(C6:Q6,"*A*") -> 1 | S6: =COUNTIF(C6:Q6,"*R*") -> 1 | T6: =IF(AND(R6=1,S6>=1),"OK","REVISAR") -> OK
A7: 1.2 | B7: Declaración del alcance y EDT | C7: A, S | D7: R | E7: C | L7: C | M7: C | N7: C | R7: =COUNTIF(C7:Q7,"*A*") -> 1 | S7: =COUNTIF(C7:Q7,"*R*") -> 1 | T7: =IF(AND(R7=1,S7>=1),"OK","REVISAR") -> OK
A8: 1.3 | B8: Cronograma, presupuesto y línea base | C8: A, S | D8: R | E8: C | R8: =COUNTIF(C8:Q8,"*A*") -> 1 | S8: =COUNTIF(C8:Q8,"*R*") -> 1 | T8: =IF(AND(R8=1,S8>=1),"OK","REVISAR") -> OK
A9: 1.4 | B9: Registro de riesgos e interesados | C9: I | D9: A, R | L9: C | M9: C | N9: C | R9: =COUNTIF(C9:Q9,"*A*") -> 1 | S9: =COUNTIF(C9:Q9,"*R*") -> 1 | T9: =IF(AND(R9=1,S9>=1),"OK","REVISAR") -> OK
A10: 1.5 | B10: Seguimiento, cambios e informes | C10: I | D10: A, R | E10: C | L10: I | M10: I | N10: I | R10: =COUNTIF(C10:Q10,"*A*") -> 1 | S10: =COUNTIF(C10:Q10,"*R*") -> 1 | T10: =IF(AND(R10=1,S10>=1),"OK","REVISAR") -> OK
A11: 1.6 | B11: Cierre y lecciones aprendidas | C11: A, S | D11: R | E11: C | L11: I | M11: I | N11: I | R11: =COUNTIF(C11:Q11,"*A*") -> 1 | S11: =COUNTIF(C11:Q11,"*R*") -> 1 | T11: =IF(AND(R11=1,S11>=1),"OK","REVISAR") -> OK
A12: 2.1 | B12: Relevamiento y reglas de negocio | D12: C | E12: A, R | F12: I | G12: I | H12: C | M12: C | N12: C | R12: =COUNTIF(C12:Q12,"*A*") -> 1 | S12: =COUNTIF(C12:Q12,"*R*") -> 1 | T12: =IF(AND(R12=1,S12>=1),"OK","REVISAR") -> OK
A13: 2.2 | B13: Planos e inventario de espacios | D13: I | E13: C | J13: R | M13: A, R | R13: =COUNTIF(C13:Q13,"*A*") -> 1 | S13: =COUNTIF(C13:Q13,"*R*") -> 2 | T13: =IF(AND(R13=1,S13>=1),"OK","REVISAR") -> OK
A14: 2.3 | B14: Módulo de reserva de escritorios | E14: A | F14: C | G14: R | H14: C | M14: I | R14: =COUNTIF(C14:Q14,"*A*") -> 1 | S14: =COUNTIF(C14:Q14,"*R*") -> 1 | T14: =IF(AND(R14=1,S14>=1),"OK","REVISAR") -> OK
A15: 2.4 | B15: Módulo de reserva de salas | E15: A | F15: C | G15: R | H15: C | M15: I | R15: =COUNTIF(C15:Q15,"*A*") -> 1 | S15: =COUNTIF(C15:Q15,"*R*") -> 1 | T15: =IF(AND(R15=1,S15>=1),"OK","REVISAR") -> OK
A16: 2.5 | B16: Check-in, check-out y liberación | E16: A | G16: R | H16: C | M16: I | R16: =COUNTIF(C16:Q16,"*A*") -> 1 | S16: =COUNTIF(C16:Q16,"*R*") -> 1 | T16: =IF(AND(R16=1,S16>=1),"OK","REVISAR") -> OK
A17: 2.6 | B17: Notificaciones y sugerencias | E17: A | G17: R | H17: C | N17: I | R17: =COUNTIF(C17:Q17,"*A*") -> 1 | S17: =COUNTIF(C17:Q17,"*R*") -> 1 | T17: =IF(AND(R17=1,S17>=1),"OK","REVISAR") -> OK
A18: 2.7 | B18: Diseño UX | E18: A | F18: R | G18: I | M18: C | N18: C | R18: =COUNTIF(C18:Q18,"*A*") -> 1 | S18: =COUNTIF(C18:Q18,"*R*") -> 1 | T18: =IF(AND(R18=1,S18>=1),"OK","REVISAR") -> OK
A19: 2.8 | B19: Implementación bot de Teams | E19: A | G19: R | H19: C | L19: C | R19: =COUNTIF(C19:Q19,"*A*") -> 1 | S19: =COUNTIF(C19:Q19,"*R*") -> 1 | T19: =IF(AND(R19=1,S19>=1),"OK","REVISAR") -> OK
A20: 2.9 | B20: Configuración web | E20: A | F20: C | G20: R | H20: C | R20: =COUNTIF(C20:Q20,"*A*") -> 1 | S20: =COUNTIF(C20:Q20,"*R*") -> 1 | T20: =IF(AND(R20=1,S20>=1),"OK","REVISAR") -> OK
A21: 3.1 | B21: SSO y SCIM con Entra ID | D21: I | I21: R | L21: A, R | O21: C | R21: =COUNTIF(C21:Q21,"*A*") -> 1 | S21: =COUNTIF(C21:Q21,"*R*") -> 2 | T21: =IF(AND(R21=1,S21>=1),"OK","REVISAR") -> OK
A22: 3.2 | B22: Sincronización con HRIS | D22: I | I22: R | L22: A | N22: C | R22: =COUNTIF(C22:Q22,"*A*") -> 1 | S22: =COUNTIF(C22:Q22,"*R*") -> 1 | T22: =IF(AND(R22=1,S22>=1),"OK","REVISAR") -> OK
A23: 3.3 | B23: Exchange, Outlook y Teams | H23: I | I23: R | L23: A | R23: =COUNTIF(C23:Q23,"*A*") -> 1 | S23: =COUNTIF(C23:Q23,"*R*") -> 1 | T23: =IF(AND(R23=1,S23>=1),"OK","REVISAR") -> OK
A24: 3.4 | B24: Seguridad y endurecimiento | D24: I | H24: C | I24: R | L24: C | O24: A, S | P24: R | R24: =COUNTIF(C24:Q24,"*A*") -> 1 | S24: =COUNTIF(C24:Q24,"*R*") -> 2 | T24: =IF(AND(R24=1,S24>=1),"OK","REVISAR") -> OK
A25: 3.5 | B25: Pruebas de integración y carga | E25: I | H25: R | I25: R | J25: C | L25: A, S | R25: =COUNTIF(C25:Q25,"*A*") -> 1 | S25: =COUNTIF(C25:Q25,"*R*") -> 2 | T25: =IF(AND(R25=1,S25>=1),"OK","REVISAR") -> OK
A26: 4.1 | B26: Impacto e interesados con RR.HH. | C26: I | K26: R | M26: C | N26: A | R26: =COUNTIF(C26:Q26,"*A*") -> 1 | S26: =COUNTIF(C26:Q26,"*R*") -> 1 | T26: =IF(AND(R26=1,S26>=1),"OK","REVISAR") -> OK
A27: 4.2 | B27: Política de trabajo flexible | C27: S | K27: R | M27: C | N27: A | O27: C | R27: =COUNTIF(C27:Q27,"*A*") -> 1 | S27: =COUNTIF(C27:Q27,"*R*") -> 1 | T27: =IF(AND(R27=1,S27>=1),"OK","REVISAR") -> OK
A28: 4.3 | B28: Comunicación y lanzamiento | C28: I | E28: C | K28: R | N28: A | Q28: R | R28: =COUNTIF(C28:Q28,"*A*") -> 1 | S28: =COUNTIF(C28:Q28,"*R*") -> 2 | T28: =IF(AND(R28=1,S28>=1),"OK","REVISAR") -> OK
A29: 4.4 | B29: Referentes y capacitación | E29: C | K29: R | N29: A | Q29: C | R29: =COUNTIF(C29:Q29,"*A*") -> 1 | S29: =COUNTIF(C29:Q29,"*R*") -> 1 | T29: =IF(AND(R29=1,S29>=1),"OK","REVISAR") -> OK
A30: 4.5 | B30: Materiales y mesa de ayuda N1 | E30: C | K30: R | L30: C | N30: A | Q30: R | R30: =COUNTIF(C30:Q30,"*A*") -> 1 | S30: =COUNTIF(C30:Q30,"*R*") -> 2 | T30: =IF(AND(R30=1,S30>=1),"OK","REVISAR") -> OK
A31: 5.1 | B31: Ambientes, migración y despliegue | I31: C | J31: R | L31: A | O31: C | R31: =COUNTIF(C31:Q31,"*A*") -> 1 | S31: =COUNTIF(C31:Q31,"*R*") -> 1 | T31: =IF(AND(R31=1,S31>=1),"OK","REVISAR") -> OK
A32: 5.2 | B32: Piloto y ajustes | D32: C | E32: A, R | F32: C | G32: R | H32: R | L32: C | M32: C | N32: C | R32: =COUNTIF(C32:Q32,"*A*") -> 1 | S32: =COUNTIF(C32:Q32,"*R*") -> 3 | T32: =IF(AND(R32=1,S32>=1),"OK","REVISAR") -> OK
A33: 5.3 | B33: UAT y acta de aceptación | C33: S | D33: I | E33: R | H33: R | L33: C | M33: C | N33: A, S | R33: =COUNTIF(C33:Q33,"*A*") -> 1 | S33: =COUNTIF(C33:Q33,"*R*") -> 2 | T33: =IF(AND(R33=1,S33>=1),"OK","REVISAR") -> OK
A34: 5.4 | B34: Go-live y estabilización (4 semanas) | C34: I | D34: A | E34: C | F34: C | G34: R | H34: R | J34: R | L34: C | M34: I | N34: C | R34: =COUNTIF(C34:Q34,"*A*") -> 1 | S34: =COUNTIF(C34:Q34,"*R*") -> 3 | T34: =IF(AND(R34=1,S34>=1),"OK","REVISAR") -> OK
A35: 5.5 | B35: Tablero y transferencia del seguimiento | E35: A, R | G35: R | L35: C | M35: S | N35: C, S | R35: =COUNTIF(C35:Q35,"*A*") -> 1 | S35: =COUNTIF(C35:Q35,"*R*") -> 2 | T35: =IF(AND(R35=1,S35>=1),"OK","REVISAR") -> OK
A36: 5.6 | B36: Informe de ocupación y recomendación | C36: I | E36: R | G36: C | M36: A, S | R36: =COUNTIF(C36:Q36,"*A*") -> 1 | S36: =COUNTIF(C36:Q36,"*R*") -> 1 | T36: =IF(AND(R36=1,S36>=1),"OK","REVISAR") -> OK
B37: Cantidad de A por rol | C37: =COUNTIF(C6:C36,"*A*") -> 4 | D37: =COUNTIF(D6:D36,"*A*") -> 3 | E37: =COUNTIF(E6:E36,"*A*") -> 10 | F37: =COUNTIF(F6:F36,"*A*") -> 0 | G37: =COUNTIF(G6:G36,"*A*") -> 0 | H37: =COUNTIF(H6:H36,"*A*") -> 0 | I37: =COUNTIF(I6:I36,"*A*") -> 0 | J37: =COUNTIF(J6:J36,"*A*") -> 0 | ... Q37: =COUNTIF(Q6:Q36,"*A*") -> 0
B38: Cantidad de R por rol | C38: =COUNTIF(C6:C36,"*R*") -> 0 | D38: =COUNTIF(D6:D36,"*R*") -> 6 | E38: =COUNTIF(E6:E36,"*R*") -> 5 | F38: =COUNTIF(F6:F36,"*R*") -> 1 | G38: =COUNTIF(G6:G36,"*R*") -> 9 | H38: =COUNTIF(H6:H36,"*R*") -> 4 | I38: =COUNTIF(I6:I36,"*R*") -> 5 | J38: =COUNTIF(J6:J36,"*R*") -> 3 | ... Q38: =COUNTIF(Q6:Q36,"*R*") -> 2
B39: Cantidad de S por rol | C39: =COUNTIF(C6:C36,"*S*") -> 6 | D39: =COUNTIF(D6:D36,"*S*") -> 1 | E39: =COUNTIF(E6:E36,"*S*") -> 0 | F39: =COUNTIF(F6:F36,"*S*") -> 0 | G39: =COUNTIF(G6:G36,"*S*") -> 0 | H39: =COUNTIF(H6:H36,"*S*") -> 0 | I39: =COUNTIF(I6:I36,"*S*") -> 0 | J39: =COUNTIF(J6:J36,"*S*") -> 0 | ... Q39: =COUNTIF(Q6:Q36,"*S*") -> 0
B41: Control de la matriz | C41: =IF(COUNTIF(T6:T36,"OK")=31,"OK: 31 filas con un A y al menos un R","REVISAR") -> OK: 31 filas con un A y al menos un R

Sheet Roles
A1: Roles y responsabilidades del equipo
A2: Participación: días-persona asignados en el presupuesto de la N2.
A4: Rol | B4: Quién | C4: Participación (N2) | D4: Responsabilidades | E4: Autoridad
A5: Project Manager | B5: Julián Ferrari (Tandem) | C5: 85,3 d-p · todo el proyecto | D5: Dirige la ejecución, mantiene la línea base, coordina los frentes y los contratos, conduce weekly e informes. | E5: Reordena tareas dentro del alcance; aplica contingencia hasta USD 5.000 por evento; escala al Sponsor.
A6: Product Owner | B6: Carolina Méndez (Tandem) | C6: 42,7 d-p · 2.1 a 2.9, piloto, UAT | D6: Prioriza el backlog, define con VCA las reglas de reserva, acepta las historias y conduce el piloto. | E6: Acepta o rechaza funcionalidades dentro del alcance; no modifica el alcance (va al Comité).
A7: Diseñador/a UX/UI | B7: Tandem | C7: 28,2 d-p · 2.3 a 2.9 y piloto | D7: Diseña la web responsive y los flujos del bot de Teams; revisa usabilidad en el piloto y la UAT. | E7: Decide patrones de interfaz dentro de la guía aprobada en H-2.
A8: Desarrolladores/as full-stack (2) | B8: Tandem | C8: 122,0 d-p · 2.3 a 2.9, 5.2, 5.4 | D8: Configuran y extienden WorkHub (escritorios, salas, check-in, notificaciones, bot, web), corrigen defectos del piloto y la estabilización; revisan el código del otro antes de integrar. | E8: Deciden la solución técnica de cada historia; los cambios de arquitectura se acuerdan con Integraciones y el PO.
A9: Especialista QA | B9: Tandem | C9: 50,1 d-p · todo el desarrollo, 3.5, 5.3 | D9: Plan y casos de prueba, regresión, pruebas de integración y carga, coordinación operativa de la UAT y evidencia de aceptación. | E9: Puede objetar un pase a producción con defectos críticos abiertos; decide el PM.
A10: Ingenieros/as de integraciones (2) | B10: Tandem | C10: 71,0 d-p · 3.1 a 3.5 | D10: SSO y SCIM con Entra ID, sincronización del HRIS, Exchange y Teams; endurecimiento y corrección de los hallazgos de la prueba de intrusión. | E10: Deciden el diseño de las interfaces dentro de las políticas de Tecnología de VCA.
A11: Ingeniero/a DevOps | B11: Tandem | C11: 22,6 d-p · 2.2, 5.1, 5.4 | D11: Aprovisiona y opera los ambientes en Azure de VCA, CI/CD y monitoreo; carga el inventario; ejecuta el corte a producción. | E11: Opera con los permisos que asigna Tecnología de VCA; no crea recursos fuera de la suscripción corporativa.
A12: Consultor/a de gestión del cambio | B12: Tandem | C12: 60,0 d-p · 4.1 a 4.5 | D12: Análisis de impacto, política de trabajo flexible, guiones de comunicación, red de referentes y capacitación; coordina a la agencia. | E12: Propone; RR.HH. de VCA aprueba (A en 4.x).
A13: Tecnología VCA | B13: Pablo Guzmán (0,5 FTE) | C13: 26,2 d-p · 3.x, 5.x | D13: Permisos de Entra ID y Teams, nube corporativa, certificación de integraciones (RA-3), mesa de ayuda. | E13: Rinde cuentas (A) por integraciones y ambientes; firma la certificación de 3.5.
A14: Servicios Generales VCA | B14: Damián Sosa (0,5 FTE) | C14: 20,5 d-p · 2.1, 2.2, 5.2, 5.3, 5.6 | D14: Planos e inventario, reglas de uso de espacios, conteos manuales de ocupación e informe de cierre. | E14: Rinde cuentas por el inventario y el informe de ocupación (RA-4).
A15: RR.HH. VCA | B15: Soledad Ibarra (0,5 FTE; 1,0 desde 01/2027) | C15: 45,0 d-p · 4.x, 5.3, 5.4 | D15: Gestión del cambio con la consultora, referentes, UAT y seguimiento de adopción posterior. | E15: Rinde cuentas por la gestión del cambio y la UAT (RA-1); firma el acta de UAT.

Sheet Interesados
A1: Registro de interesados (clasificación por poder e interés)
A2: La estrategia se deriva del cuadrante; las jefaturas reciben comunicación interactiva por su actitud de resistencia (RI-3).
A4: Interesado | B4: Int./Ext. | C4: Expectativa principal | D4: Poder | E4: Interés | F4: Actitud | G4: Estrategia | H4: Cuadrante calculado
A5: Mariana Ferreyra, CFO (Sponsor) | B5: Int. | C5: Evidencia para devolver la planta 4 dentro de USD 420.000 y del 30/04/2027 | D5: Alto | E5: Alto | F5: Apoyo | G5: Gestionar de cerca | H5: =IF(AND(D5="Alto",E5="Alto"),"Gestionar de cerca",IF(D5="Alto","Mantener satisfecho",IF(OR(E5="Alto",E5="Medio"),"Mantener informado","Monitorear"))) -> Gestionar de cerca
A6: Comité de Inversiones de VCA | B6: Int. | C6: Retorno del caso de negocio; ningún cambio sin justificar | D6: Alto | E6: Medio | F6: Neutral | G6: Mantener satisfecho | H6: =IF(AND(D6="Alto",E6="Alto"),"Gestionar de cerca",IF(D6="Alto","Mantener satisfecho",IF(OR(E6="Alto",E6="Medio"),"Mantener informado","Monitorear"))) -> Mantener satisfecho
A7: Tecnología de VCA (P. Guzmán) | B7: Int. | C7: Integraciones estables y seguras; no sumar carga operativa | D7: Alto | E7: Alto | F7: Neutral | G7: Gestionar de cerca | H7: =IF(AND(D7="Alto",E7="Alto"),"Gestionar de cerca",IF(D7="Alto","Mantener satisfecho",IF(OR(E7="Alto",E7="Medio"),"Mantener informado","Monitorear"))) -> Gestionar de cerca
A8: Servicios Generales (D. Sosa) | B8: Int. | C8: Inventario fiel y datos de ocupación confiables | D8: Medio | E8: Alto | F8: Apoyo | G8: Gestionar de cerca | H8: =IF(AND(D8="Alto",E8="Alto"),"Gestionar de cerca",IF(D8="Alto","Mantener satisfecho",IF(OR(E8="Alto",E8="Medio"),"Mantener informado","Monitorear"))) -> Mantener informado
A9: RR.HH. (S. Ibarra) | B9: Int. | C9: Adopción sin conflicto; política clara de trabajo flexible | D9: Medio | E9: Alto | F9: Apoyo | G9: Gestionar de cerca | H9: =IF(AND(D9="Alto",E9="Alto"),"Gestionar de cerca",IF(D9="Alto","Mantener satisfecho",IF(OR(E9="Alto",E9="Medio"),"Mantener informado","Monitorear"))) -> Mantener informado
A10: Seguridad de la Información y Legal de VCA | B10: Int. | C10: Cero hallazgos críticos; tratamiento de datos conforme a la Ley 25.326 | D10: Alto | E10: Bajo | F10: Neutral | G10: Mantener satisfecho | H10: =IF(AND(D10="Alto",E10="Alto"),"Gestionar de cerca",IF(D10="Alto","Mantener satisfecho",IF(OR(E10="Alto",E10="Medio"),"Mantener informado","Monitorear"))) -> Mantener satisfecho
A11: Jefaturas de área | B11: Int. | C11: Que sus equipos se sienten juntos; no perder espacio propio | D11: Medio | E11: Medio | F11: Resistencia | G11: Mantener informado (con reuniones) | H11: =IF(AND(D11="Alto",E11="Alto"),"Gestionar de cerca",IF(D11="Alto","Mantener satisfecho",IF(OR(E11="Alto",E11="Medio"),"Mantener informado","Monitorear"))) -> Mantener informado
A12: Referentes de área | B12: Int. | C12: Saber usar y explicar la herramienta antes que sus equipos | D12: Bajo | E12: Alto | F12: Apoyo | G12: Mantener informado | H12: =IF(AND(D12="Alto",E12="Alto"),"Gestionar de cerca",IF(D12="Alto","Mantener satisfecho",IF(OR(E12="Alto",E12="Medio"),"Mantener informado","Monitorear"))) -> Mantener informado
A13: Colaboradores de Catalinas (1.200) | B13: Int. | C13: Reservar rápido; que la ubicación no se use para controlar presentismo | D13: Bajo | E13: Alto | F13: Neutral / resistencia | G13: Mantener informado | H13: =IF(AND(D13="Alto",E13="Alto"),"Gestionar de cerca",IF(D13="Alto","Mantener satisfecho",IF(OR(E13="Alto",E13="Medio"),"Mantener informado","Monitorear"))) -> Mantener informado
A14: Dirección de Tandem | B14: Ext. | C14: Cumplir el contrato con margen y obtener una referencia | D14: Medio | E14: Medio | F14: Apoyo | G14: Mantener informado | H14: =IF(AND(D14="Alto",E14="Alto"),"Gestionar de cerca",IF(D14="Alto","Mantener satisfecho",IF(OR(E14="Alto",E14="Medio"),"Mantener informado","Monitorear"))) -> Mantener informado
A15: Proveedores externos (K-5 a K-9) | B15: Ext. | C15: Especificaciones claras y pagos en término | D15: Bajo | E15: Medio | F15: Apoyo | G15: Monitorear | H15: =IF(AND(D15="Alto",E15="Alto"),"Gestionar de cerca",IF(D15="Alto","Mantener satisfecho",IF(OR(E15="Alto",E15="Medio"),"Mantener informado","Monitorear"))) -> Mantener informado
A17: El cuadrante calculado es la regla general de poder e interés; la estrategia adoptada lo ajusta cuando el interés es medio o alto y el poder medio (gestionar de cerca a quien ejecuta o acepta entregables).

Sheet Comunicaciones
A1: Plan de gestión de las comunicaciones
A2: ¿Qué? ¿A quién? ¿Para qué? ¿Cómo (push, pull, interactiva)? ¿Cuándo? ¿Quién? Fechas del cronograma de la N2.
A4: ID | B4: ¿Qué? | C4: ¿A quién? | D4: ¿Para qué? | E4: ¿Cómo? | F4: ¿Cuándo? | G4: ¿Quién? | H4: Canal
A5: C-1 | B5: Daily standup | C5: Equipo de Tandem (PO, UX, DEV, QA, INT, DevOps) | D5: Avance, plan del día y bloqueos | E5: Interactiva | F5: Diaria, 09:15, 15 min | G5: PO | H5: Teams (llamada)
A6: C-2 | B6: Daily ampliada con VCA | C6: Equipo + Tecnología, Servicios Generales y RR.HH. | D6: Incidentes del piloto y de la estabilización | E6: Interactiva | F6: Diaria durante 5.2 (18/11–18/12) y 5.4 (31/03–28/04) | G6: PM | H6: Presencial en Catalinas + Teams
A7: C-3 | B7: Weekly de implementación | C7: PM, líderes de frente y referentes de VCA | D7: Estado, riesgos y acciones; destrabar decisiones | E7: Interactiva + minuta | F7: Semanal, lunes 10:00, 45 min | G7: PM | H7: Teams; minuta en SharePoint
A8: C-4 | B8: Reunión técnica de integraciones | C8: Integraciones, Tecnología VCA, DevOps y QA | D8: Avance e incidencias de Entra ID, HRIS y Exchange | E8: Interactiva + minuta | F8: Semanal, miércoles, durante 3.1–3.5 (14/10–07/01) | G8: Líder de integraciones | H8: Teams
A9: C-5 | B9: Demostración de funcionalidades | C9: PO, Servicios Generales, RR.HH. y Tecnología | D9: Validar lo construido antes de seguir | E9: Interactiva | F9: Quincenal, durante 2.3–2.9 (21/10–14/01) | G9: PO | H9: Ambiente de QA, en sala
A10: C-6 | B10: Tablero de trabajo (Jira) | C10: Equipo del proyecto | D10: Backlog, tareas, defectos y estado de cada historia | E10: Pull | F10: Permanente; se actualiza a diario | G10: PO | H10: Jira (K-4)
A11: C-7 | B11: Repositorio del proyecto | C11: Equipo e interesados internos autorizados | D11: Acta, planes, minutas, registro de riesgos y de cambios | E11: Pull | F11: Permanente | G11: PM | H11: SharePoint del proyecto (Microsoft 365 de VCA)
A12: C-8 | B12: Informe de estado semanal | C12: Sponsor y líderes de VCA | D12: Avance contra la línea base, semáforo y decisiones requeridas | E12: Push | F12: Semanal, viernes | G12: PM | H12: Correo + tablero de semáforos
A13: C-9 | B13: Reunión PM–Sponsor | C13: Sponsor | D13: Desvíos, uso de contingencia y escalamientos | E13: Interactiva | F13: Quincenal (N1, 1.9) y ante escalamiento | G13: PM | H13: Presencial
A14: C-10 | B14: Informe al Comité de Inversiones | C14: Comité de Inversiones | D14: Avance, costos, reservas, riesgos y cambios a decidir | E14: Push + presentación | F14: Mensual (N1, 1.9) | G14: Sponsor con el PM | H14: Documento + reunión
A15: C-11 | B15: Comité de control de cambios | C15: Sponsor, PM, PO y referente afectado | D15: Aprobar, diferir o rechazar solicitudes | E15: Interactiva | F15: Ante cada solicitud; resolución en 48 h hábiles (N1) | G15: PM | H15: Reunión + registro de cambios
... A21: C-17 | B21: Cierre y lecciones aprendidas | C21: Sponsor, equipo completo y referentes de VCA | D21: Aceptación final y lecciones registradas | E21: Interactiva | F21: Una vez, 26–30/04/2027 (1.6) | G21: PM | H21: Presencial
A23: Escalamiento
A24: Nivel | B24: Quién resuelve | C24: Plazo | D24: Qué se escala
A25: 1 | B25: Líder del frente | C25: 1 día hábil | D25: Problemas de su frente sin impacto en hitos ni costo.
A26: 2 | B26: Project Manager | C26: 2 días hábiles | D26: Reordenar tareas dentro del alcance; contingencia hasta USD 5.000 por evento.
A27: 3 | B27: Sponsor | C27: 48 horas hábiles (reunión extraordinaria) | D27: Riesgo sobre un hito del Acta o contingencia mayor a USD 5.000 por evento.
A28: 4 | B28: Comité de Inversiones | C28: Próxima sesión o extraordinaria | D28: Cambios de alcance, presupuesto base o fecha de cierre; impacto de costo mayor al 5 % (se escala de inmediato).
A30: Agendas de ejemplo
A31: Weekly de implementación (C-3) — Lunes 10:00 · 45 min · PM facilita, PO toma la minuta
A32: 5 min | B32: Acciones abiertas de la minuta anterior
A33: 10 min | B33: Avance por frente contra el cronograma (camino crítico y ruta del piloto primero)
A34: 10 min | B34: Riesgos: nuevos, cambios de prioridad y disparadores
A35: 10 min | B35: Bloqueos y decisiones que necesitan a VCA
A36: 5 min | B36: Solicitudes de cambio para el comité
A37: 5 min | B37: Acciones, responsables y fechas; cierre
A38: Total | B38: 45 min
A40: Daily standup (C-1) — Diaria 09:15 · 15 min · PO facilita
A41: 10 min | B41: Cada integrante: qué terminó, qué hace hoy, qué lo bloquea
A42: 3 min | B42: Revisión del tablero: tarjetas detenidas más de 2 días
A43: 2 min | B43: Bloqueos que se resuelven después, solo con los involucrados
A44: Total | B44: 15 min
A46: Reunión técnica de integraciones (C-4) — Miércoles · 60 min · Líder de integraciones facilita
A47: 10 min | B47: Estado de cada conector (Entra ID, HRIS, Exchange/Teams) frente a su criterio de aceptación
A48: 20 min | B48: Incidencias abiertas: causa, responsable y plan
A49: 15 min | B49: Permisos, ventanas de cambio y accesos que debe habilitar Tecnología de VCA
A50: 10 min | B50: Datos de prueba, ambientes y preparación de 3.4 y 3.5
...

Sheet Minuta
A1: Plantilla estandarizada de minuta
A2: Columna B: plantilla para completar. Columna D: ejemplo ilustrativo resuelto (no es un registro real).
A4: Campo | B4: Plantilla | D4: Ejemplo ilustrativo
A5: Encabezado | B5: Proyecto WKH-2026 · reunión (ID del plan) · número · fecha y hora · canal · facilitador · redactor | D5: WKH-2026 · Weekly de implementación (C-3) n.º 2 · martes 13/10/2026 10:00 (lunes feriado) · Teams · facilita J. Ferrari · redacta C. Méndez
A6: Asistentes y ausentes | B6: Nombre y rol; ausentes con aviso | D6: Ferrari (PM), Méndez (PO), líder de integraciones, Guzmán (Tecnología), Sosa (Servicios Generales), Ibarra (RR.HH.). Ausente con aviso: DevOps.
A7: Objetivo | B7: Qué decisión o resultado se esperaba | D7: Confirmar el arranque de 2.1, 3.1 y 5.1 y las compras con fecha próxima.
A8: Temas tratados | B8: Una línea por punto de la agenda, con el tiempo usado | D8: Acciones anteriores (5 min) · avance de 1.2–1.4 (10) · riesgos RI-6 y RI-16 (10) · accesos a Entra ID (10) · cambios (0) · cierre (5).
A9: Decisiones | B9: ID (D-n) · decisión · quién decide (A de la RACIS) | D9: D-1: pedir cotizaciones de K-5 y K-6 el 19/10 (A: Sponsor, a propuesta del PM). D-2: las reglas de cupos por equipo se cierran en la primera semana de 2.1 (A: PO).
A10: Acciones | B10: ID (AC-n) · acción · responsable · fecha compromiso · estado | D10: AC-1 Solicitar la ampliación de la suscripción Azure · Guzmán · 14/10 · abierta. AC-2 Enviar reglas de cupos por planta · Sosa · 20/10 · abierta. AC-3 Gestionar sandbox del HRIS · PM · 23/10 · abierta.
A11: Riesgos y cambios | B11: Riesgos nuevos o modificados (ID RI-n) y solicitudes de cambio generadas | D11: RI-6 se mantiene en prioridad media; sin solicitudes de cambio.
A12: Próxima reunión | B12: Fecha y temas pendientes | D12: Lunes 19/10/2026 10:00 · revisar AC-1 a AC-3 y el inicio de 2.3 (21/10).
A13: Distribución | B13: Se publica en el repositorio (C-7) dentro de las 24 horas; observaciones dentro de las 48 horas | D13: Publicada en el SharePoint del proyecto el 13/10 a las 16:00.
A15: ID | B15: Decisión | C15: Decide (A)
A16: D-1
A17: D-2
A18: D-3
A20: ID | B20: Acción | C20: Responsable | D20: Fecha compromiso | E20: Estado
A21: AC-1
A22: AC-2
A23: AC-3
A24: AC-4
A25: AC-5
A26: AC-6

Sheet Riesgos
A1: Registro preliminar de riesgos (análisis cualitativo)
A2: Causa → riesgo → impacto. Prioridad preliminar Alta/Media/Baja. En la N4 se agregan probabilidad e impacto (1 a 5), respuestas, disparadores y monitoreo.
A4: ID | B4: Categoría | C4: Causa | D4: Riesgo (evento) | E4: Impacto inicial | F4: Objetivo afectado | G4: Paquetes EDT | H4: Prioridad preliminar | I4: Dueño preliminar | J4: Origen
A5: RI-1 | B5: Software / operación | C5: Usuarios que no hacen check-in o check-out; geocerca imprecisa en algunas plantas | D5: El registro de ocupación no refleja el uso real | E5: Discrepancia mayor al 5 % en el informe (RA-4): la evidencia para devolver la planta 4 pierde validez | F5: Beneficio, calidad | G5: 2.5, 5.4, 5.6 | H5: Alta | I5: PO / Serv. Generales | J5: N1 (Alto/Media)
A6: RI-2 | B6: Software (integración) | C6: Permisos de Entra ID, API del HRIS menos estable que lo supuesto (S-6), límites de Microsoft Graph | D6: Demoras o incompatibilidades en las integraciones | E6: Atraso y retrabajo en 3.1–3.3; si consume la holgura, alcanza al piloto (5.2 depende de 3.1) | F6: Plazo, costo | G6: 3.1–3.5, 5.2 | H6: Media | I6: Tecnología VCA | J6: N1 (Medio/Media)
A7: RI-3 | B7: Operación (cambio) | C7: Pérdida del puesto fijo; temor a que la ubicación se use para controlar presentismo | D7: Resistencia al escritorio flexible | E7: Baja adopción (meta OP-3 del 70 %), puntaje de UAT menor a 9,0 y datos insuficientes para la decisión | F7: Beneficio, alcance | G7: 4.1–4.5, 5.3 | H7: Alta | I7: RR.HH. VCA | J7: N1 (Alto/Alta)
A8: RI-4 | B8: Negocio | C8: Demanda pico mayor a la supuesta o cláusulas del contrato de alquiler | D8: No se puede liberar la planta 4 | E8: El caso de negocio no se cumple aunque el proyecto termine bien | F8: Beneficio | G8: 5.6 | H8: Media | I8: Sponsor / Serv. Generales | J8: N1 (Alto/Baja)
A9: RI-5 | B9: Externo | C9: El cierre de balances de VCA se extiende después del 15/03 | D9: La UAT no puede empezar el 16/03 | E9: R-3 está en el camino crítico: cada día de extensión corre H-5, H-6 y el cierre del 30/04 | F9: Plazo | G9: 5.3, 5.4, 1.6 | H9: Alta | I9: Sponsor | J9: N1 (Medio/Media); sube por el camino crítico
A10: RI-6 | B10: Software | C10: El módulo de escritorios arranca con 2.1 en curso (solape SS+5) | D10: Las reglas de reserva cambian después de empezar 2.3 | E10: Retrabajo en 2.3 (holgura 10 d); más de 8 días comprometen el piloto y H-3 | F10: Plazo, costo | G10: 2.1, 2.3, 5.2 | H10: Media | I10: PO | J10: Nuevo (red N2)
A11: RI-7 | B11: Operación | C11: Piloto en diciembre con 300 usuarios (feriados del 07 y 08/12, vacaciones, cierre de año) | D11: El piloto no se completa a tiempo | E11: H-3 tiene 1 día corrido de margen; correr el piloto a enero lo mete en la ventana de balances | F11: Plazo, calidad | G11: 5.2 | H11: Alta | I11: PO | J11: Nuevo (red N2)
A12: RI-8 | B12: Operación | C12: UAT de 4 días con 120 usuarios, inmediatamente después del cierre de balances | D12: Sesiones incompletas o puntaje menor a 9,0 | E12: H-5 incumplido; en el camino crítico, cada día corre el go-live y el cierre | F12: Plazo, calidad | G12: 5.3, 5.4 | H12: Alta | I12: RR.HH. VCA / QA | J12: Nuevo (red N2)
A13: RI-9 | B13: Software (seguridad) | C13: Vulnerabilidades en la configuración, las extensiones o el bot | D13: Hallazgos críticos o altos en la prueba de intrusión | E13: RA-2 no se cumple hasta cerrarlos; retrabajo y re-test (3.4 tiene 53 d de holgura) | F13: Calidad, costo | G13: 3.4, 2.8, 2.9 | H13: Media | I13: Seg. de la Información / Integraciones | J13: Nuevo
A14: RI-10 | B14: Software (rendimiento) | C14: Dimensionamiento de ambientes; consultas de disponibilidad sobre planos en los picos de los lunes | D14: No se alcanza p95 < 500 ms con 300 usuarios concurrentes (CE-3) | E14: Ajustes de configuración, escalado en Azure con más costo de ambientes y criterio de éxito en riesgo | F14: Calidad, costo | G14: 3.5, 5.1, 5.4 | H14: Media | I14: DevOps | J14: Nuevo
A15: RI-11 | B15: Datos | C15: Registros desactualizados en el HRIS o planos que no reflejan los puestos reales | D15: Errores de sincronización mayores al 0,5 % o discrepancia de inventario mayor al 1 % | E15: Usuarios sin acceso, reservas sobre puestos inexistentes y rechazo de los entregables 2.0 y 3.0 | F15: Calidad, plazo | G15: 2.2, 3.2 | H15: Media | I15: Tecnología / Serv. Generales | J15: Nuevo
... A21: RI-17 | B21: Operación | C21: Corte a producción en las cuatro plantas el mismo día y mesa de ayuda recién formada | D21: Los incidentes de la primera semana superan la capacidad de soporte | E21: Adopción inicial baja, disponibilidad menor al 99,5 % y estabilización (crítica) extendida | F21: Plazo, calidad | G21: 4.5, 5.4 | H21: Media | I21: DevOps / Tecnología VCA | J21: Nuevo
A23: Resumen por prioridad
A24: Prioridad | B24: Cantidad
A25: Alta | B25: =COUNTIF($H$5:$H$21,"Alta") -> 5
A26: Media | B26: =COUNTIF($H$5:$H$21,"Media") -> 11
A27: Baja | B27: =COUNTIF($H$5:$H$21,"Baja") -> 1
A28: Total | B28: =SUM(B25:B27) -> 17
A29: Control | B29: =IF(B28=COUNTA(A5:A21),"OK","REVISAR") -> OK
